<mujocoinclude>
    <body name='rm2' pos="0 0 0.51">
      <geom type="box" rgba="1 0 0 0" size="0.15 0.15 0.15" pos="0 0 -0.15" density="200.0"/>

      <body name="rm2_base" pos="0 0 0">
        <geom quat="0 1 0 0" pos="0 0 0" type="mesh" contype="0" conaffinity="0" group="1" density="0"  material='rm2' mesh="rm2"/>
        <geom quat="0 1 0 0" pos="0 0 0" type="mesh" rgba="1 0 0 0" mesh="rm2" density="30.0"/>
      </body>

      <body name="steering_wheel" pos ="0 0 0">  
        <body name="steering1" pos="0.2585 0.184 -0.228">
          <inertial pos="-0.0124323 -0.000168578 0.0371705" quat="-0.000873283 0.70519 -0.0128331 0.708902" mass="0.36733" diaginertia="0.000891223 0.000726575 0.000459321"/>
          <joint name="steer_joint1" class="steer_joint"/>
          <geom pos="-0.0025 -0.028 -0.1" quat="1 0 0 0" type="mesh" contype="0" conaffinity="0" group="1" density="0" rgba="1 1 1 1" mesh="steering_left_front"/>
          <geom pos="-0.0025 -0.028 -0.1" quat="1 0 0 0" type="mesh" rgba="1 1 1 1" mesh="steering_left_front"/>
          <body name="wheel1" pos="0 -0.02 -0.185" quat="0.707105 0.707108 0 0">
            <inertial pos="-0.0124323 -0.000168578 0.0371705" quat="-0.000873283 0.70519 -0.0128331 0.708902" mass="0.36733" diaginertia="0.000891223 0.000726575 0.000459321"/>
            <joint name="wheel_joint1" class="wheel_joint"/>
            <geom quat="-3.67321e-06 0 1 0" type="mesh" contype="0" conaffinity="0" group="1" density="0" material="wheel" mesh="wheel_fix"/>
            <geom size="0.1 0.035" pos="0 0 -0.025" type="cylinder" rgba="1 0 0 0"/>
          </body>
        </body>
        <body name="steering2" pos="0.2585 -0.184 -0.228">
          <inertial pos="-0.0124323 -0.000168578 0.0371705" quat="-0.000873283 0.70519 -0.0128331 0.708902" mass="0.36733" diaginertia="0.000891223 0.000726575 0.000459321"/>
          <joint name="steer_joint2" class="steer_joint"/>
          <geom pos="-0.0025 0.028 -0.1" quat="-3.67321e-06 0 0 1" type="mesh" contype="0" conaffinity="0" group="1" density="0" rgba="1 1 1 1" mesh="steering_right_front"/>
          <geom pos="-0.0025 0.028 -0.1" quat="-3.67321e-06 0 0 1" type="mesh" rgba="1 1 1 1" mesh="steering_right_front"/>
          <body name="wheel2" pos="0 0.02 -0.185" quat="0.707105 0.707108 0 0">
            <inertial pos="-0.0124323 -0.000168578 0.0371705" quat="-0.000873283 0.70519 -0.0128331 0.708902" mass="0.36733" diaginertia="0.000891223 0.000726575 0.000459321"/>
            <joint name="wheel_joint2" class="wheel_joint"/>
            <geom type="mesh" contype="0" conaffinity="0" group="1" density="0" material="wheel" mesh="wheel_fix"/>
            <geom size="0.1 0.035" pos="0 0 0.025" type="cylinder" rgba="1 0 0 0"/>
          </body>
        </body>
        <body name="steering3" pos="-0.238 -0.184 -0.228">
          <inertial pos="-0.0124323 -0.000168578 0.0371705" quat="-0.000873283 0.70519 -0.0128331 0.708902" mass="0.36733" diaginertia="0.000891223 0.000726575 0.000459321"/>
          <joint name="steer_joint3" class="steer_joint"/>
          <geom pos="-0.0025 0.028 -0.1" quat="-3.67321e-06 0 0 1" type="mesh" contype="0" conaffinity="0" group="1" density="0" rgba="1 1 1 1" mesh="steering_left_front"/>
          <geom pos="-0.0025 0.028 -0.1" quat="-3.67321e-06 0 0 1" type="mesh" rgba="1 1 1 1" mesh="steering_left_front"/>
          <body name="wheel3" pos="0 0.02 -0.185" quat="0.707105 0.707108 0 0">
            <inertial pos="-0.0124323 -0.000168578 0.0371705" quat="-0.000873283 0.70519 -0.0128331 0.708902" mass="0.36733" diaginertia="0.000891223 0.000726575 0.000459321"/>
            <joint name="wheel_joint3" class="wheel_joint"/>
            <geom type="mesh" contype="0" conaffinity="0" group="1" density="0" material="wheel" mesh="wheel_fix"/>
            <geom size="0.1 0.035" pos="0 0 0.025" type="cylinder" rgba="1 0 0 0"/>
          </body>
        </body>
        <body name="steering4" pos="-0.238 0.184 -0.228">
          <inertial pos="-0.0124323 -0.000168578 0.0371705" quat="-0.000873283 0.70519 -0.0128331 0.708902" mass="0.36733" diaginertia="0.000891223 0.000726575 0.000459321"/>
          <joint name="steer_joint4" class="steer_joint"/>
          <geom pos="-0.0025 -0.028 -0.1" quat="1 0 0 0" type="mesh" contype="0" conaffinity="0" group="1" density="0" rgba="1 1 1 1" mesh="steering_right_front"/>
          <geom pos="-0.0025 -0.028 -0.1" quat="1 0 0 0" type="mesh" rgba="1 1 1 1" mesh="steering_right_front"/>
          <body name="wheel4" pos="0 -0.02 -0.185" quat="0.707105 0.707108 0 0">
            <inertial pos="-0.0124323 -0.000168578 0.0371705" quat="-0.000873283 0.70519 -0.0128331 0.708902" mass="0.36733" diaginertia="0.000891223 0.000726575 0.000459321"/>
            <joint name="wheel_joint4" class="wheel_joint"/>
            <geom quat="-3.67321e-06 0 1 0" type="mesh" contype="0" conaffinity="0" group="1" density="0" material="wheel" mesh="wheel_fix"/>
            <geom size="0.1 0.035" pos="0 0 -0.025" type="cylinder" rgba="1 0 0 0"/>
          </body>
        </body>
      </body>
    </body>


</mujocoinclude>
