<mujocoinclude>

    <body name="drawer" pos="0.65 0.35 0.4">
      <geom pos="0 0  0.075" size="0.2 0.2 0.01" type="box"/>
      <geom pos="0 0 -0.075" size="0.2 0.2 0.01" type="box"/>
      <geom pos=" 0.2 0 0" size="0.01 0.2 0.075" type="box"/>
      <geom pos="-0.2 0 0" size="0.01 0.2 0.075" type="box"/>
      <geom pos="0 0.2 0" size="0.2 0.01 0.075" type="box"/>

      <body name="drawer_body" pos="0 -0.015 0">
        <inertial pos="0 0 0" mass="0.001" diaginertia="0.00002 0.00002 0.00002" />
        <joint axis="0 -1 0" name="drawer_slide" pos="0 0 0" range="0 0.35" type="slide" frictionloss="1e-4"/>
        <!-- <geom pos="0 0  0.06" size="0.18 0.18 0.01" type="box"/> -->
        <geom pos="0 0 -0.06" size="0.18 0.18 0.01" type="box"/>
        <geom pos=" 0.18 0 0" size="0.01 0.18 0.06" type="box"/>
        <geom pos="-0.18 0 0" size="0.01 0.18 0.06" type="box"/>
        <geom pos="0 0.18 0" size="0.18 0.01 0.06" type="box"/>
        <geom pos="0 -0.18 0" size="0.18 0.01 0.06" type="box"/>

        <geom pos="0 -0.24 0" size="0.05 0.01 0.01" type="box"/>
        <geom pos="0.05 -0.22 0" size="0.01 0.02 0.01" type="box"/>
        <geom pos="-0.05 -0.22 0" size="0.01 0.02 0.01" type="box"/>

      </body>
    </body>

    <body name="cube_1" pos="0.6 0.22 0.52">
      <joint type="free" frictionloss="0.00001"/>
      <inertial pos="0 0 0" mass="0.001" diaginertia="0.00002 0.00002 0.00002" />
      <geom rgba="0.9 0.6 0.2 1" condim="4" solimp="2 1 0.01" solref="0.01 1" friction="1 0.005 0.0001" pos="0 0 0" size="0.025 0.025 0.025" type="box"/>
    </body>

</mujocoinclude>
