<?xml version="1.0" ?>
<!-- =================================================================================== -->
<!-- |    This document was autogenerated by xacro from mmk2.xacro                     | -->
<!-- |    EDITING THIS FILE BY HAND IS NOT RECOMMENDED                                 | -->
<!-- =================================================================================== -->
<robot name="mmk2_s_g2" xmlns:controller="http://playerstage.sourceforge.net/gazebo/xmlschema/#controller" xmlns:interface="http://playerstage.sourceforge.net/gazebo/xmlschema/#interface" xmlns:sensor="http://playerstage.sourceforge.net/gazebo/xmlschema/#sensor">

  <mujoco>
    <compiler meshdir="../models/meshes/airbot_play" balanceinertia="true" discardvisual="false" />
  </mujoco>

  <link name="world" />
  <joint name="floating_base" type="floating">
    <origin rpy="0 0 0" xyz="0 0 0" />
    <parent link="world" />
    <child link="base_footprint" />
  </joint>

  <link name="base_footprint">
  </link>
  <link name="agv_link">
    <inertial>
      <origin rpy="0 0 0" xyz="-0.00033464 -0.0025035 0.086807"/>
      <mass value="2.6454"/>
      <inertia ixx="0.034647" ixy="-0.00012407" ixz="6.5004E-06" iyy="0.042494" iyz="0.00070414" izz="0.069661"/>
    </inertial>
    <visual>
      <origin rpy="0 0 0" xyz="0 0 0"/>
      <geometry>
        <mesh filename="package://mmk2_s_g2/meshes/mmk2/visual/agv_link.STL"/>
      </geometry>
      <material name="">
        <color rgba="0.75294 0.75294 0.75294 1"/>
      </material>
    </visual>
    <collision>
      <origin rpy="0 0 0" xyz="0 0 0"/>
      <geometry>
        <mesh filename="package://mmk2_s_g2/meshes/mmk2/collision/agv_link.STL"/>
      </geometry>
    </collision>
  </link>
  <joint name="base_joint" type="fixed">
    <parent link="base_footprint"/>
    <child link="agv_link"/>
    <axis xyz="0 0 0"/>
  </joint>
  <link name="lft_wheel_link">
    <inertial>
      <origin rpy="0 0 0" xyz="2.9309E-07 5.2077E-06 -0.029871"/>
      <mass value="1.1566"/>
      <inertia ixx="0.0021045" ixy="6.963E-10" ixz="-1.9831E-08" iyy="0.0021045" iyz="-3.5159E-07" izz="0.0035528"/>
    </inertial>
    <visual>
      <origin rpy="0 0 0" xyz="0 0 0"/>
      <geometry>
        <mesh filename="package://mmk2_s_g2/meshes/mmk2/visual/lft_wheel_link.STL"/>
      </geometry>
      <material name="">
        <color rgba="0 1 0 1"/>
      </material>
    </visual>
    <collision>
      <origin rpy="0 0 0" xyz="0 0 0"/>
      <geometry>
        <mesh filename="package://mmk2_s_g2/meshes/mmk2/collision/lft_wheel_link.STL"/>
      </geometry>
    </collision>
  </link>
  <joint name="lft_wheel_joint" type="continuous">
    <origin rpy="1.5708 0 -1.5708" xyz="0.13551 0.02371 0.052015"/>
    <parent link="agv_link"/>
    <child link="lft_wheel_link"/>
    <axis xyz="0 0 -1"/>
  </joint>
  <link name="rgt_wheel_link">
    <inertial>
      <origin rpy="0 0 0" xyz="2.9312E-07 5.2196E-06 0.029871"/>
      <mass value="1.1566"/>
      <inertia ixx="0.0021045" ixy="-8.6762E-11" ixz="1.9824E-08" iyy="0.0021045" iyz="3.5159E-07" izz="0.0035528"/>
    </inertial>
    <visual>
      <origin rpy="0 0 0" xyz="0 0 0"/>
      <geometry>
        <mesh filename="package://mmk2_s_g2/meshes/mmk2/visual/rgt_wheel_link.STL"/>
      </geometry>
      <material name="">
        <color rgba="0 1 0 1"/>
      </material>
    </visual>
    <collision>
      <origin rpy="0 0 0" xyz="0 0 0"/>
      <geometry>
        <mesh filename="package://mmk2_s_g2/meshes/mmk2/collision/rgt_wheel_link.STL"/>
      </geometry>
    </collision>
  </link>
  <joint name="rgt_wheel_joint" type="continuous">
    <origin rpy="1.5708 0 -1.5708" xyz="-0.13499 0.02371 0.052015"/>
    <parent link="agv_link"/>
    <child link="rgt_wheel_link"/>
    <axis xyz="0 0 -1"/>
  </joint>
  <link name="rgt_behind_wheel_link">
    <inertial>
      <origin rpy="0 0 0" xyz="0.0098797 -0.26998 -0.044087"/>
      <mass value="0.15002"/>
      <inertia ixx="0.00016534" ixy="1.4827E-07" ixz="-2.9264E-07" iyy="0.00014609" iyz="4.0633E-05" izz="9.3638E-05"/>
    </inertial>
    <visual>
      <origin rpy="0 0 0" xyz="0 0 0"/>
      <geometry>
        <mesh filename="package://mmk2_s_g2/meshes/mmk2/visual/rgt_behind_wheel_link.STL"/>
      </geometry>
      <material name="">
        <color rgba="1 1 1 1"/>
      </material>
    </visual>
    <collision>
      <origin rpy="0 0 0" xyz="0 0 0"/>
      <geometry>
        <mesh filename="package://mmk2_s_g2/meshes/mmk2/collision/rgt_behind_wheel_link.STL"/>
      </geometry>
    </collision>
  </link>
  <joint name="rgt_behind_wheel_joint" type="fixed">
    <origin rpy="0 0 0" xyz="-0.099989 0.15755 0.0595"/>
    <parent link="agv_link"/>
    <child link="rgt_behind_wheel_link"/>
    <axis xyz="0 0 0"/>
  </joint>
  <link name="lft_behind_wheel_link">
    <inertial>
      <origin rpy="0 0 0" xyz="-0.01012 -0.26998 -0.044087"/>
      <mass value="0.15002"/>
      <inertia ixx="0.00016534" ixy="1.4827E-07" ixz="-2.9264E-07" iyy="0.00014609" iyz="4.0633E-05" izz="9.3638E-05"/>
    </inertial>
    <visual>
      <origin rpy="0 0 0" xyz="0 0 0"/>
      <geometry>
        <mesh filename="package://mmk2_s_g2/meshes/mmk2/visual/lft_behind_wheel_link.STL"/>
      </geometry>
      <material name="">
        <color rgba="1 1 1 1"/>
      </material>
    </visual>
    <collision>
      <origin rpy="0 0 0" xyz="0 0 0"/>
      <geometry>
        <mesh filename="package://mmk2_s_g2/meshes/mmk2/collision/lft_behind_wheel_link.STL"/>
      </geometry>
    </collision>
  </link>
  <joint name="lft_behind_wheel_joint" type="fixed">
    <origin rpy="0 0 0" xyz="0.10001 0.15755 0.0595"/>
    <parent link="agv_link"/>
    <child link="lft_behind_wheel_link"/>
    <axis xyz="0 0 0"/>
  </joint>
  <link name="rgt_front_wheel_link">
    <inertial>
      <origin rpy="0 0 0" xyz="-0.01012 0.30602 -0.044087"/>
      <mass value="0.15002"/>
      <inertia ixx="0.00016534" ixy="1.4827E-07" ixz="-2.9264E-07" iyy="0.00014609" iyz="4.0633E-05" izz="9.3637E-05"/>
    </inertial>
    <visual>
      <origin rpy="0 0 0" xyz="0 0 0"/>
      <geometry>
        <mesh filename="package://mmk2_s_g2/meshes/mmk2/visual/rgt_front_wheel_link.STL"/>
      </geometry>
      <material name="">
        <color rgba="1 1 1 1"/>
      </material>
    </visual>
    <collision>
      <origin rpy="0 0 0" xyz="0 0 0"/>
      <geometry>
        <mesh filename="package://mmk2_s_g2/meshes/mmk2/collision/rgt_front_wheel_link.STL"/>
      </geometry>
    </collision>
  </link>
  <joint name="rgt_front_wheel_joint" type="fixed">
    <origin rpy="0 0 0" xyz="-0.089989 -0.13045 0.0595"/>
    <parent link="agv_link"/>
    <child link="rgt_front_wheel_link"/>
    <axis xyz="0 0 0"/>
  </joint>
  <link name="lft_front_wheel_link">
    <inertial>
      <origin rpy="0 0 0" xyz="0.0098797 0.30602 -0.044087"/>
      <mass value="0.15002"/>
      <inertia ixx="0.00016534" ixy="1.4827E-07" ixz="-2.9264E-07" iyy="0.00014609" iyz="4.0633E-05" izz="9.3637E-05"/>
    </inertial>
    <visual>
      <origin rpy="0 0 0" xyz="0 0 0"/>
      <geometry>
        <mesh filename="package://mmk2_s_g2/meshes/mmk2/visual/lft_front_wheel_link.STL"/>
      </geometry>
      <material name="">
        <color rgba="1 1 1 1"/>
      </material>
    </visual>
    <collision>
      <origin rpy="0 0 0" xyz="0 0 0"/>
      <geometry>
        <mesh filename="package://mmk2_s_g2/meshes/mmk2/collision/lft_front_wheel_link.STL"/>
      </geometry>
    </collision>
  </link>
  <joint name="lft_front_wheel_joint" type="fixed">
    <origin rpy="0 0 0" xyz="0.090011 -0.13045 0.0595"/>
    <parent link="agv_link"/>
    <child link="lft_front_wheel_link"/>
    <axis xyz="0 0 0"/>
  </joint>

  <link name="left_flange">
    <visual>
      <origin rpy="0. -1.5707964 0. " xyz="0.0040002 0.0219004 -0.0221024"/>
      <geometry>
        <mesh filename="package://mmk2_s_g2/meshes/flange/visual/flange.obj" scale="1. 1. 1."/>
      </geometry>
    </visual>
    <collision>
      <origin rpy="0. -1.5707964 0. " xyz="0.0040002 0.0219004 -0.0221024"/>
      <geometry>
        <mesh filename="package://mmk2_s_g2/meshes/flange/collision/flange.obj" scale="1. 1. 1."/>
      </geometry>
    </collision>
  </link>
  <link name="left_base_link">
    <inertial>
      <origin rpy="0 0 0" xyz="-0.007609 -0.00070281 0.038353"/>
      <mass value="0.7358"/>
      <inertia ixx="0.00056691" ixy="7.5556E-06" ixz="1.0335E-06" iyy="0.00068606" iyz="7.7985E-07" izz="0.0010143"/>
    </inertial>
    <visual>
      <origin rpy="0 0 0" xyz="0 0 0"/>
      <geometry>
        <mesh filename="package://mmk2_s_g2/meshes/airbot_play_v3_1/visual/base_link.STL"/>
      </geometry>
      <material name="">
        <color rgba="0.75294 0.75294 0.75294 1"/>
      </material>
    </visual>
    <collision>
      <origin rpy="0 0 0" xyz="0 0 0"/>
      <geometry>
        <mesh filename="package://mmk2_s_g2/meshes/airbot_play_v3_1/collision/base_link.STL"/>
      </geometry>
    </collision>
  </link>
  <link name="left_link1">
    <inertial>
      <origin rpy="0 0 0" xyz="-6.8774E-06 -0.0010314 -0.014457"/>
      <mass value="0.78638"/>
      <inertia ixx="0.00026059" ixy="-2.1857E-07" ixz="1.3032E-06" iyy="0.00035988" iyz="1.5738E-05" izz="0.00030082"/>
    </inertial>
    <visual>
      <origin rpy="0 0 0" xyz="0 0 0"/>
      <geometry>
        <mesh filename="package://mmk2_s_g2/meshes/airbot_play_v3_1/visual/link1.STL"/>
      </geometry>
      <material name="">
        <color rgba="0.75294 0.75294 0.75294 1"/>
      </material>
    </visual>
    <collision>
      <origin rpy="0 0 0" xyz="0 0 0"/>
      <geometry>
        <mesh filename="package://mmk2_s_g2/meshes/airbot_play_v3_1/collision/link1.STL"/>
      </geometry>
    </collision>
  </link>
  <joint name="left_joint1" type="revolute">
    <origin rpy="0 0 0" xyz="0 0 0.1117"/>
    <parent link="left_base_link"/>
    <child link="left_link1"/>
    <axis xyz="0 0 1"/>
    <limit effort="12" lower="-2.7475" upper="2.7475" velocity="0.5"/>
  </joint>
  <link name="left_link2">
    <inertial>
      <origin rpy="0 0 0" xyz="0.17545 0.0056978 0.005978"/>
      <mass value="1.0247"/>
      <inertia ixx="0.00040289" ixy="-0.00012909" ixz="4.6597E-05" iyy="0.003174" iyz="9.7791E-06" izz="0.0033885"/>
    </inertial>
    <visual>
      <origin rpy="0 0 0" xyz="0 0 0"/>
      <geometry>
        <mesh filename="package://mmk2_s_g2/meshes/airbot_play_v3_1/visual/link2.STL"/>
      </geometry>
      <material name="">
        <color rgba="0.75294 0.75294 0.75294 1"/>
      </material>
    </visual>
    <collision>
      <origin rpy="0 0 0" xyz="0 0 0"/>
      <geometry>
        <mesh filename="package://mmk2_s_g2/meshes/airbot_play_v3_1/collision/link2.STL"/>
      </geometry>
    </collision>
  </link>
  <joint name="left_joint2" type="revolute">
    <origin rpy="-1.5691 -0.38673 3.1409" xyz="0 0 0"/>
    <parent link="left_link1"/>
    <child link="left_link2"/>
    <axis xyz="0 0 1"/>
    <limit effort="12" lower="-2.9656" upper="0.1744" velocity="0.5"/>
  </joint>
  <link name="left_link3">
    <inertial>
      <origin rpy="0 0 0" xyz="-7.1479E-05 0.10773 0.010341"/>
      <mass value="0.59643"/>
      <inertia ixx="0.0011117" ixy="2.9694E-07" ixz="-1.1205E-07" iyy="0.00022817" iyz="0.00014247" izz="0.0011062"/>
    </inertial>
    <visual>
      <origin rpy="0 0 0" xyz="0 0 0"/>
      <geometry>
        <mesh filename="package://mmk2_s_g2/meshes/airbot_play_v3_1/visual/link3.STL"/>
      </geometry>
      <material name="">
        <color rgba="0.75294 0.75294 0.75294 1"/>
      </material>
    </visual>
    <collision>
      <origin rpy="0 0 0" xyz="0 0 0"/>
      <geometry>
        <mesh filename="package://mmk2_s_g2/meshes/airbot_play_v3_1/collision/link3.STL"/>
      </geometry>
    </collision>
  </link>
  <joint name="left_joint3" type="revolute">
    <origin rpy="0 0.0015895 1.9575" xyz="0.27009 0 0"/>
    <parent link="left_link2"/>
    <child link="left_link3"/>
    <axis xyz="0 0 1"/>
    <limit effort="12" lower="-0.08722" upper="3.14" velocity="0.5"/>
  </joint>
  <link name="left_link4">
    <inertial>
      <origin rpy="0 0 0" xyz="3.2214E-05 -0.00064503 -0.020926"/>
      <mass value="0.37017"/>
      <inertia ixx="0.00011024" ixy="6.4278E-09" ixz="-5.8907E-08" iyy="0.00013798" iyz="-7.8592E-06" izz="0.00011351"/>
    </inertial>
    <visual>
      <origin rpy="0 0 0" xyz="0 0 0"/>
      <geometry>
        <mesh filename="package://mmk2_s_g2/meshes/airbot_play_v3_1/visual/link4.STL"/>
      </geometry>
      <material name="">
        <color rgba="0.75294 0.75294 0.75294 1"/>
      </material>
    </visual>
    <collision>
      <origin rpy="0 0 0" xyz="0 0 0"/>
      <geometry>
        <mesh filename="package://mmk2_s_g2/meshes/airbot_play_v3_1/collision/link4.STL"/>
      </geometry>
    </collision>
  </link>
  <joint name="left_joint4" type="revolute">
    <origin rpy="-1.5708 -1.5708 0" xyz="8.2128E-05 0.29015 0"/>
    <parent link="left_link3"/>
    <child link="left_link4"/>
    <axis xyz="0 0 1"/>
    <limit effort="3" lower="-3.01" upper="3.01" velocity="1"/>
  </joint>
  <link name="left_link5">
    <inertial>
      <origin rpy="0 0 0" xyz="1.0183E-05 0.033415 0.0052853"/>
      <mass value="0.40859"/>
      <inertia ixx="0.00014324" ixy="-1.2363E-07" ixz="-1.6092E-07" iyy="0.00015285" iyz="1.3894E-05" izz="0.00014936"/>
    </inertial>
    <visual>
      <origin rpy="0 0 0" xyz="0 0 0"/>
      <geometry>
        <mesh filename="package://mmk2_s_g2/meshes/airbot_play_v3_1/visual/link5.STL"/>
      </geometry>
      <material name="">
        <color rgba="0.75294 0.75294 0.75294 1"/>
      </material>
    </visual>
    <collision>
      <origin rpy="0 0 0" xyz="0 0 0"/>
      <geometry>
        <mesh filename="package://mmk2_s_g2/meshes/airbot_play_v3_1/collision/link5.STL"/>
      </geometry>
    </collision>
  </link>
  <joint name="left_joint5" type="revolute">
    <origin rpy="1.5708 0 0" xyz="0 0 0"/>
    <parent link="left_link4"/>
    <child link="left_link5"/>
    <axis xyz="0 0 1"/>
    <limit effort="3" lower="-1.76" upper="1.76" velocity="1"/>
  </joint>
  <link name="left_link6">
    <inertial>
      <origin rpy="0 0 0" xyz="-0.011264 1.1814E-06 2.7354E-06"/>
      <mass value="0.14593"/>
      <inertia ixx="2.3175E-05" ixy="-8.0893E-10" ixz="-2.5166E-14" iyy="1.2978E-05" iyz="-2.9196E-09" izz="1.2976E-05"/>
    </inertial>
    <visual>
      <origin rpy="0 0 0" xyz="0 0 0"/>
      <geometry>
        <mesh filename="package://mmk2_s_g2/meshes/airbot_play_v3_1/visual/link6.STL"/>
      </geometry>
      <material name="">
        <color rgba="0.75294 0.75294 0.75294 1"/>
      </material>
    </visual>
    <collision>
      <origin rpy="0 0 0" xyz="0 0 0"/>
      <geometry>
        <mesh filename="package://mmk2_s_g2/meshes/airbot_play_v3_1/collision/link6.STL"/>
      </geometry>
    </collision>
  </link>
  <joint name="left_joint6" type="revolute">
    <origin rpy="0 0 1.5708" xyz="0 0.0864 0"/>
    <parent link="left_link5"/>
    <child link="left_link6"/>
    <axis xyz="1 0 0"/>
    <limit effort="3" lower="-3.009" upper="3.009" velocity="1"/>
  </joint>
  <joint name="left_arm_to_flange" type="fixed">
    <origin rpy="0 0 0" xyz="0 0 0"/>
    <parent link="left_link6"/>
    <child link="left_flange"/>
  </joint>
  
  <link name="left_eef_base_link">
    <inertial>
      <origin rpy="0 0 0" xyz="0.046303 -9.8611E-06 -1.4675E-05"/>
      <mass value="0.26507"/>
      <inertia ixx="348.3689417" ixy="0.2800965" ixz="-0.0560724" iyy="198.5351968" iyz="1.3076668" izz="449.2281738"/>
    </inertial>
    <visual>
      <origin rpy="0 0 0" xyz="0 0 0"/>
      <geometry>
        <mesh filename="package://mmk2_s_g2/meshes/G2/visual/base_link.STL"/>
      </geometry>
      <material name="">
        <color rgba="0.75294 0.75294 0.75294 1"/>
      </material>
    </visual>
    <collision>
      <origin rpy="0 0 0" xyz="0 0 0"/>
      <geometry>
        <mesh filename="package://mmk2_s_g2/meshes/G2/collision/base_link.STL"/>
      </geometry>
    </collision>
  </link>
  <link name="left_eef_link1">
    <inertial>
      <origin rpy="0 0 0" xyz="-0.015415 -0.066964 0.014312"/>
      <mass value="0.078003"/>
      <inertia ixx="34.1905834" ixy="-0.1388713" ixz="-0.4368816" iyy="54.1781125" iyz="6.8453757" izz="27.3518738"/>
    </inertial>
    <visual>
      <origin rpy="0 0 0" xyz="0 0 0"/>
      <geometry>
        <mesh filename="package://mmk2_s_g2/meshes/G2/visual/link1.STL"/>
      </geometry>
      <material name="">
        <color rgba="0.75294 0.75294 0.75294 1"/>
      </material>
    </visual>
    <collision>
      <origin rpy="0 0 0" xyz="0 0 0"/>
      <geometry>
        <mesh filename="package://mmk2_s_g2/meshes/G2/collision/link1.STL"/>
      </geometry>
    </collision>
  </link>
  <joint name="left_eef_joint1" type="prismatic">
    <origin rpy="0 1.5708 0" xyz="0.0736 0.05 -0.015"/>
    <parent link="left_eef_base_link"/>
    <child link="left_eef_link1"/>
    <axis xyz="0 1 0"/>
    <limit effort="3" lower="-0.034" upper="0" velocity="1"/>
    <mimic joint="left_eef_active_joint" multiplier="-0.034" offset="0"/>
  </joint>
  <link name="left_eef_link2">
    <inertial>
      <origin rpy="0 0 0" xyz="-0.014585 0.066964 0.014312"/>
      <mass value="0.078003"/>
      <inertia ixx="34.1905834" ixy="-0.1388713" ixz="0.4368816" iyy="54.1781125" iyz="-6.8453757" izz="27.3518738"/>
    </inertial>
    <visual>
      <origin rpy="0 0 0" xyz="0 0 0"/>
      <geometry>
        <mesh filename="package://mmk2_s_g2/meshes/G2/visual/link2.STL"/>
      </geometry>
      <material name="">
        <color rgba="0.75294 0.75294 0.75294 1"/>
      </material>
    </visual>
    <collision>
      <origin rpy="0 0 0" xyz="0 0 0"/>
      <geometry>
        <mesh filename="package://mmk2_s_g2/meshes/G2/collision/link2.STL"/>
      </geometry>
    </collision>
  </link>
  <joint name="left_eef_joint2" type="prismatic">
    <origin rpy="0 1.5708 0" xyz="0.0736 -0.05 -0.015"/>
    <parent link="left_eef_base_link"/>
    <child link="left_eef_link2"/>
    <axis xyz="0 1 0"/>
    <limit effort="3" lower="0" upper="0.034" velocity="1"/>
    <mimic joint="left_eef_active_joint" multiplier="0.034" offset="0"/>
  </joint>
  <joint name="left_eef_active_joint" type="revolute">
    <origin rpy="0 0 0" xyz="0 0 0"/>
    <axis xyz="0 0 1"/>
    <parent link="left_eef_base_link"/>
    <child link="left_eef_rotate_motor"/>
    <limit effort="20" lower="0" upper="1" velocity="3.1415926"/>
  </joint>
  <link name="left_eef_rotate_motor"/>
  <joint name="left_gripper_connector" type="fixed">
    <origin rpy="0 0 0" xyz="0.009 0 0"/>
    <parent link="left_flange"/>
    <child link="left_eef_base_link"/>
  </joint>
  <link name="left_end_link">
    <inertial>
      <origin rpy="0 0 0" xyz="0 0 0"/>
      <mass value="1E-15"/>
      <inertia ixx="1E-11" ixy="1E-15" ixz="1E-15" iyy="1E-11" iyz="1E-15" izz="1E-11"/>
    </inertial>
  </link>
  <joint name="left_eef__end_joint" type="fixed">
    <origin rpy="0 0 0" xyz="0.1593 0 0"/>
    <parent link="left_eef_base_link"/>
    <child link="left_end_link"/>
  </joint>
  
  <link name="right_flange">
    <visual>
      <origin rpy="0. -1.5707964 0. " xyz="0.0040002 0.0219004 -0.0221024"/>
      <geometry>
        <mesh filename="package://mmk2_s_g2/meshes/flange/visual/flange.obj" scale="1. 1. 1."/>
      </geometry>
    </visual>
    <collision>
      <origin rpy="0. -1.5707964 0. " xyz="0.0040002 0.0219004 -0.0221024"/>
      <geometry>
        <mesh filename="package://mmk2_s_g2/meshes/flange/collision/flange.obj" scale="1. 1. 1."/>
      </geometry>
    </collision>
  </link>
  <link name="right_base_link">
    <inertial>
      <origin rpy="0 0 0" xyz="-0.007609 -0.00070281 0.038353"/>
      <mass value="0.7358"/>
      <inertia ixx="0.00056691" ixy="7.5556E-06" ixz="1.0335E-06" iyy="0.00068606" iyz="7.7985E-07" izz="0.0010143"/>
    </inertial>
    <visual>
      <origin rpy="0 0 0" xyz="0 0 0"/>
      <geometry>
        <mesh filename="package://mmk2_s_g2/meshes/airbot_play_v3_1/visual/base_link.STL"/>
      </geometry>
      <material name="">
        <color rgba="0.75294 0.75294 0.75294 1"/>
      </material>
    </visual>
    <collision>
      <origin rpy="0 0 0" xyz="0 0 0"/>
      <geometry>
        <mesh filename="package://mmk2_s_g2/meshes/airbot_play_v3_1/collision/base_link.STL"/>
      </geometry>
    </collision>
  </link>
  <link name="right_link1">
    <inertial>
      <origin rpy="0 0 0" xyz="-6.8774E-06 -0.0010314 -0.014457"/>
      <mass value="0.78638"/>
      <inertia ixx="0.00026059" ixy="-2.1857E-07" ixz="1.3032E-06" iyy="0.00035988" iyz="1.5738E-05" izz="0.00030082"/>
    </inertial>
    <visual>
      <origin rpy="0 0 0" xyz="0 0 0"/>
      <geometry>
        <mesh filename="package://mmk2_s_g2/meshes/airbot_play_v3_1/visual/link1.STL"/>
      </geometry>
      <material name="">
        <color rgba="0.75294 0.75294 0.75294 1"/>
      </material>
    </visual>
    <collision>
      <origin rpy="0 0 0" xyz="0 0 0"/>
      <geometry>
        <mesh filename="package://mmk2_s_g2/meshes/airbot_play_v3_1/collision/link1.STL"/>
      </geometry>
    </collision>
  </link>
  <joint name="right_joint1" type="revolute">
    <origin rpy="0 0 0" xyz="0 0 0.1117"/>
    <parent link="right_base_link"/>
    <child link="right_link1"/>
    <axis xyz="0 0 1"/>
    <limit effort="12" lower="-2.7475" upper="2.7475" velocity="0.5"/>
  </joint>
  <link name="right_link2">
    <inertial>
      <origin rpy="0 0 0" xyz="0.17545 0.0056978 0.005978"/>
      <mass value="1.0247"/>
      <inertia ixx="0.00040289" ixy="-0.00012909" ixz="4.6597E-05" iyy="0.003174" iyz="9.7791E-06" izz="0.0033885"/>
    </inertial>
    <visual>
      <origin rpy="0 0 0" xyz="0 0 0"/>
      <geometry>
        <mesh filename="package://mmk2_s_g2/meshes/airbot_play_v3_1/visual/link2.STL"/>
      </geometry>
      <material name="">
        <color rgba="0.75294 0.75294 0.75294 1"/>
      </material>
    </visual>
    <collision>
      <origin rpy="0 0 0" xyz="0 0 0"/>
      <geometry>
        <mesh filename="package://mmk2_s_g2/meshes/airbot_play_v3_1/collision/link2.STL"/>
      </geometry>
    </collision>
  </link>
  <joint name="right_joint2" type="revolute">
    <origin rpy="-1.5691 -0.38673 3.1409" xyz="0 0 0"/>
    <parent link="right_link1"/>
    <child link="right_link2"/>
    <axis xyz="0 0 1"/>
    <limit effort="12" lower="-2.9656" upper="0.1744" velocity="0.5"/>
  </joint>
  <link name="right_link3">
    <inertial>
      <origin rpy="0 0 0" xyz="-7.1479E-05 0.10773 0.010341"/>
      <mass value="0.59643"/>
      <inertia ixx="0.0011117" ixy="2.9694E-07" ixz="-1.1205E-07" iyy="0.00022817" iyz="0.00014247" izz="0.0011062"/>
    </inertial>
    <visual>
      <origin rpy="0 0 0" xyz="0 0 0"/>
      <geometry>
        <mesh filename="package://mmk2_s_g2/meshes/airbot_play_v3_1/visual/link3.STL"/>
      </geometry>
      <material name="">
        <color rgba="0.75294 0.75294 0.75294 1"/>
      </material>
    </visual>
    <collision>
      <origin rpy="0 0 0" xyz="0 0 0"/>
      <geometry>
        <mesh filename="package://mmk2_s_g2/meshes/airbot_play_v3_1/collision/link3.STL"/>
      </geometry>
    </collision>
  </link>
  <joint name="right_joint3" type="revolute">
    <origin rpy="0 0.0015895 1.9575" xyz="0.27009 0 0"/>
    <parent link="right_link2"/>
    <child link="right_link3"/>
    <axis xyz="0 0 1"/>
    <limit effort="12" lower="-0.08722" upper="3.14" velocity="0.5"/>
  </joint>
  <link name="right_link4">
    <inertial>
      <origin rpy="0 0 0" xyz="3.2214E-05 -0.00064503 -0.020926"/>
      <mass value="0.37017"/>
      <inertia ixx="0.00011024" ixy="6.4278E-09" ixz="-5.8907E-08" iyy="0.00013798" iyz="-7.8592E-06" izz="0.00011351"/>
    </inertial>
    <visual>
      <origin rpy="0 0 0" xyz="0 0 0"/>
      <geometry>
        <mesh filename="package://mmk2_s_g2/meshes/airbot_play_v3_1/visual/link4.STL"/>
      </geometry>
      <material name="">
        <color rgba="0.75294 0.75294 0.75294 1"/>
      </material>
    </visual>
    <collision>
      <origin rpy="0 0 0" xyz="0 0 0"/>
      <geometry>
        <mesh filename="package://mmk2_s_g2/meshes/airbot_play_v3_1/collision/link4.STL"/>
      </geometry>
    </collision>
  </link>
  <joint name="right_joint4" type="revolute">
    <origin rpy="-1.5708 -1.5708 0" xyz="8.2128E-05 0.29015 0"/>
    <parent link="right_link3"/>
    <child link="right_link4"/>
    <axis xyz="0 0 1"/>
    <limit effort="3" lower="-3.01" upper="3.01" velocity="1"/>
  </joint>
  <link name="right_link5">
    <inertial>
      <origin rpy="0 0 0" xyz="1.0183E-05 0.033415 0.0052853"/>
      <mass value="0.40859"/>
      <inertia ixx="0.00014324" ixy="-1.2363E-07" ixz="-1.6092E-07" iyy="0.00015285" iyz="1.3894E-05" izz="0.00014936"/>
    </inertial>
    <visual>
      <origin rpy="0 0 0" xyz="0 0 0"/>
      <geometry>
        <mesh filename="package://mmk2_s_g2/meshes/airbot_play_v3_1/visual/link5.STL"/>
      </geometry>
      <material name="">
        <color rgba="0.75294 0.75294 0.75294 1"/>
      </material>
    </visual>
    <collision>
      <origin rpy="0 0 0" xyz="0 0 0"/>
      <geometry>
        <mesh filename="package://mmk2_s_g2/meshes/airbot_play_v3_1/collision/link5.STL"/>
      </geometry>
    </collision>
  </link>
  <joint name="right_joint5" type="revolute">
    <origin rpy="1.5708 0 0" xyz="0 0 0"/>
    <parent link="right_link4"/>
    <child link="right_link5"/>
    <axis xyz="0 0 1"/>
    <limit effort="3" lower="-1.76" upper="1.76" velocity="1"/>
  </joint>
  <link name="right_link6">
    <inertial>
      <origin rpy="0 0 0" xyz="-0.011264 1.1814E-06 2.7354E-06"/>
      <mass value="0.14593"/>
      <inertia ixx="2.3175E-05" ixy="-8.0893E-10" ixz="-2.5166E-14" iyy="1.2978E-05" iyz="-2.9196E-09" izz="1.2976E-05"/>
    </inertial>
    <visual>
      <origin rpy="0 0 0" xyz="0 0 0"/>
      <geometry>
        <mesh filename="package://mmk2_s_g2/meshes/airbot_play_v3_1/visual/link6.STL"/>
      </geometry>
      <material name="">
        <color rgba="0.75294 0.75294 0.75294 1"/>
      </material>
    </visual>
    <collision>
      <origin rpy="0 0 0" xyz="0 0 0"/>
      <geometry>
        <mesh filename="package://mmk2_s_g2/meshes/airbot_play_v3_1/collision/link6.STL"/>
      </geometry>
    </collision>
  </link>
  <joint name="right_joint6" type="revolute">
    <origin rpy="0 0 1.5708" xyz="0 0.0864 0"/>
    <parent link="right_link5"/>
    <child link="right_link6"/>
    <axis xyz="1 0 0"/>
    <limit effort="3" lower="-3.009" upper="3.009" velocity="1"/>
  </joint>
  <joint name="right_arm_to_flange" type="fixed">
    <origin rpy="0 0 0" xyz="0 0 0"/>
    <parent link="right_link6"/>
    <child link="right_flange"/>
  </joint>
  
  <link name="right_eef_base_link">
    <inertial>
      <origin rpy="0 0 0" xyz="0.046303 -9.8611E-06 -1.4675E-05"/>
      <mass value="0.26507"/>
      <inertia ixx="348.3689417" ixy="0.2800965" ixz="-0.0560724" iyy="198.5351968" iyz="1.3076668" izz="449.2281738"/>
    </inertial>
    <visual>
      <origin rpy="0 0 0" xyz="0 0 0"/>
      <geometry>
        <mesh filename="package://mmk2_s_g2/meshes/G2/visual/base_link.STL"/>
      </geometry>
      <material name="">
        <color rgba="0.75294 0.75294 0.75294 1"/>
      </material>
    </visual>
    <collision>
      <origin rpy="0 0 0" xyz="0 0 0"/>
      <geometry>
        <mesh filename="package://mmk2_s_g2/meshes/G2/collision/base_link.STL"/>
      </geometry>
    </collision>
  </link>
  <link name="right_eef_link1">
    <inertial>
      <origin rpy="0 0 0" xyz="-0.015415 -0.066964 0.014312"/>
      <mass value="0.078003"/>
      <inertia ixx="34.1905834" ixy="-0.1388713" ixz="-0.4368816" iyy="54.1781125" iyz="6.8453757" izz="27.3518738"/>
    </inertial>
    <visual>
      <origin rpy="0 0 0" xyz="0 0 0"/>
      <geometry>
        <mesh filename="package://mmk2_s_g2/meshes/G2/visual/link1.STL"/>
      </geometry>
      <material name="">
        <color rgba="0.75294 0.75294 0.75294 1"/>
      </material>
    </visual>
    <collision>
      <origin rpy="0 0 0" xyz="0 0 0"/>
      <geometry>
        <mesh filename="package://mmk2_s_g2/meshes/G2/collision/link1.STL"/>
      </geometry>
    </collision>
  </link>
  <joint name="right_eef_joint1" type="prismatic">
    <origin rpy="0 1.5708 0" xyz="0.0736 0.05 -0.015"/>
    <parent link="right_eef_base_link"/>
    <child link="right_eef_link1"/>
    <axis xyz="0 1 0"/>
    <limit effort="3" lower="-0.034" upper="0" velocity="1"/>
    <mimic joint="right_eef_active_joint" multiplier="-0.034" offset="0"/>
  </joint>
  <link name="right_eef_link2">
    <inertial>
      <origin rpy="0 0 0" xyz="-0.014585 0.066964 0.014312"/>
      <mass value="0.078003"/>
      <inertia ixx="34.1905834" ixy="-0.1388713" ixz="0.4368816" iyy="54.1781125" iyz="-6.8453757" izz="27.3518738"/>
    </inertial>
    <visual>
      <origin rpy="0 0 0" xyz="0 0 0"/>
      <geometry>
        <mesh filename="package://mmk2_s_g2/meshes/G2/visual/link2.STL"/>
      </geometry>
      <material name="">
        <color rgba="0.75294 0.75294 0.75294 1"/>
      </material>
    </visual>
    <collision>
      <origin rpy="0 0 0" xyz="0 0 0"/>
      <geometry>
        <mesh filename="package://mmk2_s_g2/meshes/G2/collision/link2.STL"/>
      </geometry>
    </collision>
  </link>
  <joint name="right_eef_joint2" type="prismatic">
    <origin rpy="0 1.5708 0" xyz="0.0736 -0.05 -0.015"/>
    <parent link="right_eef_base_link"/>
    <child link="right_eef_link2"/>
    <axis xyz="0 1 0"/>
    <limit effort="3" lower="0" upper="0.034" velocity="1"/>
    <mimic joint="right_eef_active_joint" multiplier="0.034" offset="0"/>
  </joint>
  <joint name="right_eef_active_joint" type="revolute">
    <origin rpy="0 0 0" xyz="0 0 0"/>
    <axis xyz="0 0 1"/>
    <parent link="right_eef_base_link"/>
    <child link="right_eef_rotate_motor"/>
    <limit effort="20" lower="0" upper="1" velocity="3.1415926"/>
  </joint>
  <link name="right_eef_rotate_motor"/>
  <joint name="right_gripper_connector" type="fixed">
    <origin rpy="0 0 0" xyz="0.009 0 0"/>
    <parent link="right_flange"/>
    <child link="right_eef_base_link"/>
  </joint>
  <link name="right_end_link">
    <inertial>
      <origin rpy="0 0 0" xyz="0 0 0"/>
      <mass value="1E-15"/>
      <inertia ixx="1E-11" ixy="1E-15" ixz="1E-15" iyy="1E-11" iyz="1E-15" izz="1E-11"/>
    </inertial>
  </link>
  <joint name="right_eef__end_joint" type="fixed">
    <origin rpy="0 0 0" xyz="0.1593 0 0"/>
    <parent link="right_eef_base_link"/>
    <child link="right_end_link"/>
  </joint>
  
  <link name="underboard_link">
    <inertial>
      <origin rpy="0 0 0" xyz="-2.4003E-05 0.022863 0.0044812"/>
      <mass value="0.88853"/>
      <inertia ixx="0.013467" ixy="2.4931E-08" ixz="-2.7615E-08" iyy="0.0093481" iyz="1.0343E-05" izz="0.022806"/>
    </inertial>
    <visual>
      <origin rpy="0 0 0" xyz="0 0 0"/>
      <geometry>
        <mesh filename="package://mmk2_s_g2/meshes/mmk2/visual/underboard_link.STL"/>
      </geometry>
      <material name="">
        <color rgba="0.79216 0.81961 0.93333 1"/>
      </material>
    </visual>
    <collision>
      <origin rpy="0 0 0" xyz="0 0 0"/>
      <geometry>
        <mesh filename="package://mmk2_s_g2/meshes/mmk2/collision/underboard_link.STL"/>
      </geometry>
    </collision>
  </link>
  <joint name="underboard_joint" type="fixed">
    <origin rpy="0 0 0" xyz="1.3256E-05 -0.010746 0.2"/>
    <parent link="agv_link"/>
    <child link="underboard_link"/>
    <axis xyz="0 0 0"/>
  </joint>
  <link name="skin_link">
    <inertial>
      <origin rpy="0 0 0" xyz="0.0053539 0.091833 0.53214"/>
      <mass value="11.501"/>
      <inertia ixx="0.63248" ixy="9.6841E-05" ixz="0.00090478" iyy="0.61528" iyz="0.0053871" izz="0.026756"/>
    </inertial>
    <visual>
      <origin rpy="0 0 0" xyz="0 0 0"/>
      <geometry>
        <mesh filename="package://mmk2_s_g2/meshes/mmk2/visual/skin_link.STL"/>
      </geometry>
      <material name="">
        <color rgba="0.79216 0.81961 0.93333 1"/>
      </material>
    </visual>
    <collision>
      <origin rpy="0 0 0" xyz="0 0 0"/>
      <geometry>
        <mesh filename="package://mmk2_s_g2/meshes/mmk2/collision/skin_link.STL"/>
      </geometry>
    </collision>
  </link>
  <joint name="skin_joint" type="fixed">
    <origin rpy="0 0 0" xyz="0 0.016967 0.008"/>
    <parent link="underboard_link"/>
    <child link="skin_link"/>
    <axis xyz="0 0 0"/>
  </joint>
  <link name="rail_link">
    <inertial>
      <origin rpy="0 0 0" xyz="-0.0017204 -0.028658 0.67523"/>
      <mass value="3.696"/>
      <inertia ixx="0.34541" ixy="-4.3993E-06" ixz="1.0075E-10" iyy="0.34608" iyz="-3.1067E-07" izz="0.002139"/>
    </inertial>
    <visual>
      <origin rpy="0 0 0" xyz="0 0 0"/>
      <geometry>
        <mesh filename="package://mmk2_s_g2/meshes/mmk2/visual/rail_link.STL"/>
      </geometry>
      <material name="">
        <color rgba="0.79216 0.81961 0.93333 1"/>
      </material>
    </visual>
    <collision>
      <origin rpy="0 0 0" xyz="0 0 0"/>
      <geometry>
        <mesh filename="package://mmk2_s_g2/meshes/mmk2/collision/rail_link.STL"/>
      </geometry>
    </collision>
  </link>
  <joint name="rail_joint" type="fixed">
    <origin rpy="0 0 0" xyz="0 0.0505 0"/>
    <parent link="underboard_link"/>
    <child link="rail_link"/>
    <axis xyz="0 0 0"/>
  </joint>
  <link name="slide_link">
    <inertial>
      <origin rpy="0 0 0" xyz="-0.0017204 0.040092 -0.42778"/>
      <mass value="3.696"/>
      <inertia ixx="0.34541" ixy="-4.3993E-06" ixz="1.0075E-10" iyy="0.34608" iyz="-3.1067E-07" izz="0.002139"/>
    </inertial>
    <visual>
      <origin rpy="0 0 0" xyz="0 0 0"/>
      <geometry>
        <mesh filename="package://mmk2_s_g2/meshes/mmk2/visual/slide_link.STL"/>
      </geometry>
      <material name="">
        <color rgba="0.79216 0.81961 0.93333 1"/>
      </material>
    </visual>
    <collision>
      <origin rpy="0 0 0" xyz="0 0 0"/>
      <geometry>
        <mesh filename="package://mmk2_s_g2/meshes/mmk2/collision/slide_link.STL"/>
      </geometry>
    </collision>
  </link>
  <joint name="slide_joint" type="prismatic">
    <origin rpy="0 0 0" xyz="0 -0.06875 1.123"/>
    <parent link="rail_link"/>
    <child link="slide_link"/>
    <axis xyz="0 0 -1"/>
    <limit effort="100" lower="-0.055" upper="0.893" velocity="0.3"/>
  </joint>
  <link name="assembly_board_link">
    <inertial>
      <origin rpy="0 0 0" xyz="1.5189E-05 -0.02189 -0.0045526"/>
      <mass value="0.99791"/>
      <inertia ixx="0.0049193" ixy="5.8964E-07" ixz="-1.6335E-06" iyy="0.0073418" iyz="-0.00029608" izz="0.0049597"/>
    </inertial>
    <visual>
      <origin rpy="0 0 0" xyz="0 0 0"/>
      <geometry>
        <mesh filename="package://mmk2_s_g2/meshes/mmk2/visual/assembly_board_link.STL"/>
      </geometry>
      <material name="">
        <color rgba="0.79216 0.81961 0.93333 1"/>
      </material>
    </visual>
    <collision>
      <origin rpy="0 0 0" xyz="0 0 0"/>
      <geometry>
        <mesh filename="package://mmk2_s_g2/meshes/mmk2/collision/assembly_board_link.STL"/>
      </geometry>
    </collision>
  </link>
  <joint name="assembly_board_joint" type="fixed">
    <origin rpy="0 0 0" xyz="0 -0.02825 -0.01675"/>
    <parent link="slide_link"/>
    <child link="assembly_board_link"/>
    <axis xyz="0 0 0"/>
  </joint>
  <joint name="left_arm_base_joint" type="fixed">
    <origin rpy="1.5707963267949 3.141592654 0.78539816339745" xyz="0.0987031946288887 0.0272132410891314 2.82485111384734E-05"/>
    <parent link="assembly_board_link"/>
    <child link="left_base_link"/>
    <axis xyz="0 0 0"/>
  </joint>
  <joint name="right_arm_base_joint" type="fixed">
    <origin rpy="1.5707963267949 0 -0.78539816339745" xyz="-0.0987031946288892 0.0272132410891324 -2.8248511136697E-05"/>
    <parent link="assembly_board_link"/>
    <child link="right_base_link"/>
    <axis xyz="0 0 0"/>
  </joint>
  <link name="slide_connect_head_link">
    <inertial>
      <origin rpy="0 0 0" xyz="0.00065072 0.053782 -0.0030337"/>
      <mass value="0.075076"/>
      <inertia ixx="0.00014993" ixy="1.4704E-09" ixz="-4.8848E-11" iyy="5.3443E-05" iyz="2.2106E-05" izz="0.0001809"/>
    </inertial>
    <visual>
      <origin rpy="0 0 0" xyz="0 0 0"/>
      <geometry>
        <mesh filename="package://mmk2_s_g2/meshes/mmk2/visual/slide_connect_head_link.STL"/>
      </geometry>
      <material name="">
        <color rgba="0.79216 0.81961 0.93333 1"/>
      </material>
    </visual>
    <collision>
      <origin rpy="0 0 0" xyz="0 0 0"/>
      <geometry>
        <mesh filename="package://mmk2_s_g2/meshes/mmk2/collision/slide_connect_head_link.STL"/>
      </geometry>
    </collision>
  </link>
  <joint name="slide_connect_head_joint" type="fixed">
    <origin rpy="0 0 0" xyz="0 -0.1265 -0.02675"/>
    <parent link="assembly_board_link"/>
    <child link="slide_connect_head_link"/>
    <axis xyz="0 0 0"/>
  </joint>
  <link name="head_yaw_link">
    <inertial>
      <origin rpy="0 0 0" xyz="-7.9123E-06 -3.619E-05 -0.013763"/>
      <mass value="0.067958"/>
      <inertia ixx="1.427E-05" ixy="-3.1145E-08" ixz="2.1206E-10" iyy="1.442E-05" iyz="-4.6926E-09" izz="2.5823E-05"/>
    </inertial>
    <visual>
      <origin rpy="0 0 0" xyz="0 0 0"/>
      <geometry>
        <mesh filename="package://mmk2_s_g2/meshes/mmk2/visual/head_yaw_link.STL"/>
      </geometry>
      <material name="">
        <color rgba="0.79216 0.81961 0.93333 1"/>
      </material>
    </visual>
    <collision>
      <origin rpy="0 0 0" xyz="0 0 0"/>
      <geometry>
        <mesh filename="package://mmk2_s_g2/meshes/mmk2/collision/head_yaw_link.STL"/>
      </geometry>
    </collision>
  </link>
  <joint name="head_yaw_joint" type="revolute">
    <origin rpy="0 0 0" xyz="0 0 0.04808"/>
    <parent link="slide_connect_head_link"/>
    <child link="head_yaw_link"/>
    <axis xyz="0 0 -1"/>
    <limit effort="0" lower="-0.4" upper="0.5" velocity="0"/>
  </joint>
  <link name="yaw_connect_link">
    <inertial>
      <origin rpy="0 0 0" xyz="-0.0171 -0.00048947 0.014035"/>
      <mass value="0.015153"/>
      <inertia ixx="8.4781E-06" ixy="8.4766E-09" ixz="2.1644E-06" iyy="8.1822E-06" iyz="6.1955E-08" izz="5.8747E-06"/>
    </inertial>
    <visual>
      <origin rpy="0 0 0" xyz="0 0 0"/>
      <geometry>
        <mesh filename="package://mmk2_s_g2/meshes/mmk2/visual/yaw_connect_link.STL"/>
      </geometry>
      <material name="">
        <color rgba="0.79216 0.81961 0.93333 1"/>
      </material>
    </visual>
    <collision>
      <origin rpy="0 0 0" xyz="0 0 0"/>
      <geometry>
        <mesh filename="package://mmk2_s_g2/meshes/mmk2/collision/yaw_connect_link.STL"/>
      </geometry>
    </collision>
  </link>
  <joint name="yaw_connect_joint" type="fixed">
    <origin rpy="0 0 0" xyz="0 0 0.01"/>
    <parent link="head_yaw_link"/>
    <child link="yaw_connect_link"/>
    <axis xyz="0 0 0"/>
  </joint>
  <link name="head_pitch_link">
    <inertial>
      <origin rpy="0 0 0" xyz="-3.6189E-05 7.9119E-06 -0.013763"/>
      <mass value="0.067958"/>
      <inertia ixx="1.442E-05" ixy="3.1146E-08" ixz="-4.6925E-09" iyy="1.427E-05" iyz="-2.121E-10" izz="2.5823E-05"/>
    </inertial>
    <visual>
      <origin rpy="0 0 0" xyz="0 0 0"/>
      <geometry>
        <mesh filename="package://mmk2_s_g2/meshes/mmk2/visual/head_pitch_link.STL"/>
      </geometry>
      <material name="">
        <color rgba="0.79216 0.81961 0.93333 1"/>
      </material>
    </visual>
    <collision>
      <origin rpy="0 0 0" xyz="0 0 0"/>
      <geometry>
        <mesh filename="package://mmk2_s_g2/meshes/mmk2/collision/head_pitch_link.STL"/>
      </geometry>
    </collision>
  </link>
  <joint name="head_pitch_joint" type="revolute">
    <origin rpy="1.5708 0 1.5994" xyz="0.016073 0.00046009 0.028995"/>
    <parent link="yaw_connect_link"/>
    <child link="head_pitch_link"/>
    <axis xyz="0 0 -1"/>
    <limit effort="0" lower="-0.55" upper="0.35" velocity="0"/>
  </joint>
  <link name="pitch_connect_link">
    <inertial>
      <origin rpy="0 0 0" xyz="-0.038695 0.135 -0.022771"/>
      <mass value="0.69934"/>
      <inertia ixx="0.0027933" ixy="-0.00024431" ixz="1.6206E-08" iyy="0.0018608" iyz="5.1733E-06" izz="0.0021406"/>
    </inertial>
    <visual>
      <origin rpy="0 0 0" xyz="0 0 0"/>
      <geometry>
        <mesh filename="package://mmk2_s_g2/meshes/mmk2/visual/pitch_connect_link.STL"/>
      </geometry>
      <material name="">
        <color rgba="0.79216 0.81961 0.93333 1"/>
      </material>
    </visual>
    <collision>
      <origin rpy="0 0 0" xyz="0 0 0"/>
      <geometry>
        <mesh filename="package://mmk2_s_g2/meshes/mmk2/collision/pitch_connect_link.STL"/>
      </geometry>
    </collision>
  </link>
  <joint name="pitch_connect_joint" type="fixed">
    <origin rpy="0 0 0" xyz="0 0 0.006"/>
    <parent link="head_pitch_link"/>
    <child link="pitch_connect_link"/>
    <axis xyz="0 0 0"/>
  </joint>
</robot>
