<mujocoinclude>
  <body name="lft_arm_link1" pos="0 0 0.1172">
    <inertial pos="7.9126e-05 -0.002527 -0.0041359" quat="0.696716 0.716558 0.0238919 -0.0236876" mass="0.5571" diaginertia="0.000346294 0.000325437 0.000286269"/>
    <joint name="lft_arm_joint1" class='joint1'/>
    <geom name='lft_arm_link1' rgba="0.1 0.1 0.1 1" mesh="link1" class="obj_visual"/>
    <body name="lft_arm_link2" quat="0.135866 0.135867 -0.69393 0.693932">
      <inertial pos="0.22493 0.0047721 0.008023" quat="-0.210875 0.632473 -0.273056 0.693506" mass="0.64621" diaginertia="0.00516535 0.00505042 0.000418626"/>
      <joint name="lft_arm_joint2" class='joint2'/>
      <geom type="box" pos="0.08 0.015 0" euler="0 0 0.15" size="0.11 0.03 0.04" rgba="1 0 0 0.00"/>
      <geom type="box" pos="0.235 0.015 0" euler="0 0 -0.3" size="0.065 0.025 0.045" rgba="1 0 0 0.00"/>
      <geom mesh="link2_0" material="Paint_Matte_Black" class="obj_visual"/>
      <geom mesh="link2_1" material="Paint_Metallic_Cool_Grey" class="obj_visual"/>
      <body name="lft_arm_link3" pos="0.27009 0 0" quat="0.192144 0 0 -0.981367">
        <inertial pos="0.16813 -5.5576e-05 0.0031184" quat="0.511278 0.488423 0.489191 0.510617" mass="0.26829" diaginertia="0.0031527 0.0030951 0.000239403"/>
        <joint name="lft_arm_joint3" class='joint3'/>
        <geom type="box" pos="0.13 0 0" size="0.13 0.025 0.025" rgba="1 0 0 0.00"/>
        <geom mesh="link3_0" material="Paint_Matte_Black" class="obj_visual"/>
        <geom mesh="link3_1" material="Paint_Metallic_Cool_Grey" class="obj_visual"/>
        <body name="lft_arm_link4" pos="0.29015 0 0" quat="-2.59734e-06 0.707105 2.59735e-06 0.707108">
          <inertial pos="5.2436e-06 0.00040412 -0.03228" quat="0.999969 -0.000174762 -0.00792041 -6.98144e-05" mass="0.34876" diaginertia="0.000423574 0.000412 0.000126826"/>
          <joint name="lft_arm_joint4" class='joint4'/>
          <geom type="cylinder" pos="0 0 0" size="0.03 0.03" euler="1.5708 0 0" rgba="1 0 0 0.00"/>
          <geom name='lft_arm_link4' rgba="0.1 0.1 0.1 1" mesh="link4" class="obj_visual"/>
          <body name="lft_arm_link5" quat="0.707105 0.707108 0 0">
            <inertial pos="8.3328e-06 0.026148 0.002525" quat="0.531568 0.4663 0.4663 0.531568" mass="0.36132" diaginertia="0.0004677 0.000432922 0.000178178"/>
            <joint name="lft_arm_joint5" class='joint5'/>
            <geom type="cylinder" pos="0 0.06 0" size="0.03 0.03" euler="1.5708 0 0" rgba="1 0 0 0.00"/>
            <geom mesh="link5_0" material="Paint_Matte_Black" class="obj_visual"/>
            <geom mesh="link5_1" material="Paint_Metallic_Cool_Grey" class="obj_visual"/>
            <body name="lft_arm_link6" pos="0 0.23645 0" quat="0.5 -0.5 0.5 0.5">
              <inertial pos="0.020482 2.5483e-05 -0.079685" mass="0.40081" diaginertia="0.00109963 0.00109963 0.00109963"/>
              <joint name="lft_arm_joint6" class='joint6'/>
              <geom type="cylinder" pos="0 0 -0.11" size="0.03 0.03" euler="0 0 0" rgba="1 0 0 0.00"/>
              <geom type="box" pos="0 0 -0.07" size="0.025 0.08 0.015" rgba="1 0 0 0.00"/>
              <geom rgba="0.1 0.1 0.1 1" mesh="link6" class="obj_visual"/>
              <body pos="-0.105 0 -0.12" euler="3.1416 0 1.5708">
                <camera name="lft_handeye" euler="-0.5236 0 0" fovy="72.5376526571421"/>
              </body>
              <site name="lft_endpoint" pos='0 0 0' euler="0 -1.5708 0" size='0.001' type='sphere'/>
              <body name="lft_finger_right_link" pos="0 0 0">
                <inertial pos="-0.048742 0.0096369 0.00044322" quat="0.757393 0.0415116 0.0313705 0.650883" mass="0.0626" diaginertia="2.79281e-05 1.90181e-05 1.21737e-05"/>
                <joint name="lft_finger_right_joint" class='finger2'/>
                <!-- ==================================================================================== -->
                <!-- <geom condim="4" solimp="2 1 0.01" solref="0.01 1" friction="1 0.005 0.0001" type="box" pos="0.012 0.002 0.002" size="0.012 0.002 0.01" rgba="1 0 0 0.00"/>
                <geom condim="4" solimp="2 1 0.01" solref="0.01 1" friction="1 0.005 0.0001" type="box" pos="-0.012 0.002 0.005" size="0.012 0.002 0.02" rgba="1 0 0 0.00"/>
                <geom condim="4" solimp="2 1 0.01" solref="0.01 1" friction="1 0.005 0.0001" type="box" pos="-0.036 0.002 0.0" size="0.012 0.002 0.03" rgba="1 0 0 0.00"/>
                <geom mesh="right" rgba="0.1 0.1 0.1 1" class="obj_visual"/> -->
                <!-- or -->
                <geom condim="4" solimp="2 1 0.01" solref="0.01 1" friction="1 0.005 0.0001" type="mesh" mesh="right" rgba="0.1 0.1 0.1 1"/>
                <!-- ==================================================================================== -->
              </body>
              <body name="lft_finger_left_link" pos="0 0 0">
                <inertial pos="-0.049039 -0.0096764 0.00038868" quat="0.650491 0.0296695 0.0398251 0.757889" mass="0.061803" diaginertia="2.74809e-05 1.88104e-05 1.19127e-05"/>
                <joint name="lft_finger_left_joint" class='finger1'/>
                <!-- ==================================================================================== -->
                <!-- <geom condim="4" solimp="2 1 0.01" solref="0.01 1" friction="1 0.005 0.0001" type="box" pos="0.012 -0.002 0.002" size="0.012 0.002 0.01" rgba="1 0 0 0.00"/>
                <geom condim="4" solimp="2 1 0.01" solref="0.01 1" friction="1 0.005 0.0001" type="box" pos="-0.012 -0.002 0.005" size="0.012 0.002 0.02" rgba="1 0 0 0.00"/>
                <geom condim="4" solimp="2 1 0.01" solref="0.01 1" friction="1 0.005 0.0001" type="box" pos="-0.036 -0.002 0.0" size="0.012 0.002 0.03" rgba="1 0 0 0.00"/>
                <geom mesh="left" rgba="0.1 0.1 0.1 1" class="obj_visual"/> -->
                <!-- or -->
                <geom condim="4" solimp="2 1 0.01" solref="0.01 1" friction="1 0.005 0.0001" type="mesh" mesh="left" rgba="0.1 0.1 0.1 1"/>
                <!-- ==================================================================================== -->
              </body>
            </body>
          </body>
        </body>
      </body>
    </body>
  </body>

</mujocoinclude>