<mujocoinclude>

  <site name="tok2_base" pos='-0.02371 0 0' size='0.001' type='sphere'/>
  <geom type="mesh" rgba="0.1 0.1 0.1 1" mesh="tok2_base" class="obj_visual"/>

  <geom euler="0 0 0" type="box" rgba="1 0 0 0" size="0.21 0.2 0.11" pos="-0.015 0 0.129" density="725.0"/>
  <geom type="box" rgba="1 0 0 0" size="0.125 0.15 0.675" pos="-0.08 0 0.915" density="200.0"/>

  <geom name='rgt_front_wheel'  pos=" 0.13045 -0.089989 0.0585" mass='1.1566' type="sphere" size='0.06' rgba="1 1 1 0" condim='1' priority='1'/>
  <geom name='lft_front_wheel'  pos=" 0.13045  0.090011 0.0585" mass='1.1566' type="sphere" size='0.06' rgba="1 1 1 0" condim='1' priority='1'/>
  <geom name='rgt_behind_wheel' pos="-0.15755 -0.099989 0.0585" mass='1.1566' type="sphere" size='0.06' rgba="1 1 1 0" condim='1' priority='1'/>
  <geom name='lft_behind_wheel' pos="-0.15755  0.10001  0.0585" mass='1.1566' type="sphere" size='0.06' rgba="1 1 1 0" condim='1' priority='1'/>

  <geom mesh='rgt_front_wheel_link'  euler="0 0 1.5708" pos=" 0.13045 -0.089989 0.085" rgba="0.2 0.2 0.2 1" class="obj_visual"/>
  <geom mesh='lft_front_wheel_link'  euler="0 0 1.5708" pos=" 0.13045  0.090011 0.085" rgba="0.2 0.2 0.2 1" class="obj_visual"/>
  <geom mesh='rgt_behind_wheel_link' euler="0 0 1.5708" pos="-0.15755 -0.099989 0.085" rgba="0.2 0.2 0.2 1" class="obj_visual"/>
  <geom mesh='lft_behind_wheel_link' euler="0 0 1.5708" pos="-0.15755  0.10001  0.085" rgba="0.2 0.2 0.2 1" class="obj_visual"/>

  <body name="agv_link" pos="0.01 0 0">
    <geom type="box" rgba="1 0 0 0" size="0.125 0.15 0.675" pos="-0.08 0 0.915" density="200.0"/>
    <geom mesh="mmk2_agv_0" material="Paint_Matte_Black__1" class="obj_visual"/>
    <geom mesh="mmk2_agv_1" material="Copper_Textured__1_1" class="obj_visual"/>
    <geom mesh="mmk2_agv_2" material="Paint_Metallic_Cool_Grey__1" class="obj_visual"/>
    <geom mesh="mmk2_agv_3" material="Paint_Matte_Black__1" class="obj_visual"/>
    <geom mesh="mmk2_agv_4" rgba="0.592 0.9 0.9 1" class="obj_visual"/>
  </body>

  <body pos="0.3577 0 1.0675" euler="0 1.8326 -1.5708">
    <inertial pos="0 0 0" quat="1 0 0 0" mass="1e-6" diaginertia="1e-12 1e-12 1e-12"/>
    <camera name='base_camera' euler="3.1416 0 0" fovy='72.5376526571421'/>
  </body>

  <body name="lft_wheel_link" pos="-0.02371 0.16325 0.082" euler="1.5708 0 0">
    <inertial pos="2.9309e-07 5.2077e-06 -0.029871" quat="0.28052 0.649078 -0.280681 0.649018" mass="1.1566" diaginertia="0.0035528 0.0021045 0.0021045"/>
    <joint name="lft_wheel_joint" class='tok2_wheel'/>
    <geom name='lft_wheel' type="mesh" rgba="0.2 0.2 0.2 1" mesh="lft_wheel_link" class="obj_visual"/>
    <geom pos="0 0 0" type="sphere" size='0.0837' rgba="0 1 0 0"/>
  </body>

  <body name="rgt_wheel_link" pos="-0.02371 -0.16325 0.082" euler="1.5708 0 0">
    <inertial pos="2.9312e-07 5.2196e-06 0.029871" quat="0.620108 0.339813 -0.620017 0.339959" mass="1.1566" diaginertia="0.0035528 0.0021045 0.0021045"/>
    <joint name="rgt_wheel_joint" class='tok2_wheel'/>
    <geom name='rgt_wheel' type="mesh" rgba="0.2 0.2 0.2 1" mesh="rgt_wheel_link" class="obj_visual"/>
    <geom pos="0 0 0" type="sphere" size='0.0837' rgba="0 1 0 0"/>
  </body>

  <body name="lft_arm" pos="0.39275 0.2736 0.7895" euler="0 0 -0.7854">
    <geom mesh="arm_base_1" material="Paint_Matte_Black" class="obj_visual"/>
    <include file="tok2/lft_arm.xml"/>
  </body>
  <body name="rgt_arm" pos="0.39275 -0.2736 0.7895" euler="0 0 0.7854">
    <geom mesh="arm_base_1" material="Paint_Matte_Black" class="obj_visual"/>
    <include file="tok2/rgt_arm.xml"/>
  </body>

</mujocoinclude>
