<mujoco model="right leap hand">
  <compiler angle="radian" autolimits="true" meshdir="assets"/>

  <option integrator="implicitfast" cone="elliptic" impratio="10"/>

  <default>
    <default class="right_leap">
      <!-- <site size="0.002" rgba="0.5 0.5 0.5 0.3" /> -->
      <joint axis="0 0 -1" armature="0.01"/>
      <position inheritrange="1" kp="20" dampratio="1"/>
      <default class="obj_visual">
        <geom group="2" type="mesh" contype="0" conaffinity="0" density="0" material="black"/>
      </default>
      <default class="collision">
        <geom group="3" type="mesh"/>
      </default>
    </default> 
    <!-- <default class="sensor_unit">
      <site size="0.0005 0.001 0.001" rgba="1 0 1 1" type="box"/>
    </default> -->
  </default>

  <asset>
    <material name="black" rgba=".2 .2 .2 1"/>

    <mesh file="../../meshes/leap_hand_sensor/palm_lower.stl"/>
    <mesh file="../../meshes/leap_hand_sensor/mcp_joint.stl"/>
    <mesh file="../../meshes/leap_hand_sensor/pip.stl"/>
    <mesh file="../../meshes/leap_hand_sensor/dip.stl"/>
    <mesh file="../../meshes/leap_hand_sensor/fingertip.stl"/>
    <mesh file="../../meshes/leap_hand_sensor/thumb_pip.stl"/>
    <mesh file="../../meshes/leap_hand_sensor/thumb_dip.stl"/>
    <mesh file="../../meshes/leap_hand_sensor/thumb_fingertip.stl"/>
  </asset>

  <worldbody>
    <light pos="0 0 2"/>
    <body name="palm_lower" childclass="right_leap" pos="0 0 .2" quat="0 1 0 0">
    <!-- <freejoint/> -->
      <inertial pos="0 0 0" quat="0.497095 0.495942 -0.509424 0.497419" mass="0.237"
        diaginertia="0.000529322 0.000354076 0.000260868"/>
      <geom pos="-0.0200952 0.0257578 -0.0347224" quat="1 0 0 0" mesh="palm_lower" class="obj_visual"/>
      <geom pos="-0.0200952 0.0257578 -0.0347224" quat="1 0 0 0" mesh="palm_lower" class="collision"/>
      <body name="mcp_joint" pos="-0.00709525 0.0230578 -0.0187224" quat="1 1 1 -1">
        <inertial pos="0 0 0" quat="0.388585 0.626468 -0.324549 0.592628" mass="0.044"
          diaginertia="1.47756e-05 1.31982e-05 6.0802e-06"/>
        <joint name="index_mcp_bend" range="-0.314 2.23" actuatorfrcrange="-5 5"/>
        <geom pos="0.0084069 0.00776624 0.0146574" quat="1 0 0 0" mesh="mcp_joint" class="obj_visual"/>
        <geom pos="0.0084069 0.00776624 0.0146574" quat="1 0 0 0" mesh="mcp_joint" class="collision"/>
        <body name="pip" pos="-0.0122 0.0381 0.0145" quat="1 -1 -1 1">
          <inertial pos="0 0 0" quat="0.709913 0.704273 -0.000363156 0.00475427" mass="0.032"
            diaginertia="4.7981e-06 4.23406e-06 2.86184e-06"/>
          <joint name="index_mcp_widen" range="-1.047 1.047" actuatorfrcrange="-5 5"/>
          <geom pos="0.00964336 0.0003 0.000784034" quat="1 -1 -1 -1" mesh="pip" class="obj_visual"/>
          <geom pos="0.00964336 0.0003 0.000784034" quat="1 -1 -1 -1" mesh="pip" class="collision"/>
          <body name="dip" pos="0.015 0.0143 -0.013" quat="1 1 -1 1">
            <inertial pos="0 0 0" quat="-0.252689 0.659216 0.238844 0.666735" mass="0.037"
              diaginertia="6.68256e-06 6.24841e-06 5.02002e-06"/>
            <joint name="index_pip" range="-0.506 1.885" actuatorfrcrange="-5 5"/>
            <geom pos="0.0211334 -0.00843212 0.00978509" quat="0 -1 0 0" mesh="dip" class="obj_visual"/>
            <geom pos="0.0211334 -0.00843212 0.00978509" quat="0 -1 0 0" mesh="dip" class="collision"/>
            <body name="fingertip" pos="-4.08806e-09 -0.0361 0.0002">
              <inertial pos="0 0 0" quat="0.706755 0.706755 0.0223155 0.0223155" mass="0.016"
                diaginertia="3.37527e-06 2.863e-06 1.54873e-06"/>
              <joint name="index_dip" range="-0.366 2.042" actuatorfrcrange="-5 5"/>
              <geom pos="0.0132864 -0.00611424 0.0145" quat="0 1 0 0" mesh="fingertip" class="obj_visual"/>
              <geom pos="0.0132864 -0.00611424 0.0145" quat="0 1 0 0" mesh="fingertip" class="collision"/>
              <include file="index_sensor_array.xml"/>  
            </body>
          </body>
        </body>
      </body>
      <body name="mcp_joint_2" pos="-0.00709525 -0.0223922 -0.0187224" quat="1 1 1 -1">
        <inertial pos="0 0 0" quat="0.388585 0.626468 -0.324549 0.592628" mass="0.044"
          diaginertia="1.47756e-05 1.31982e-05 6.0802e-06"/>
        <joint name="mid_mcp_bend" range="-0.314 2.23" actuatorfrcrange="-5 5"/>
        <geom pos="0.0084069 0.00776624 0.0146574" quat="1 0 0 0" mesh="mcp_joint" class="obj_visual"/>
        <geom pos="0.0084069 0.00776624 0.0146574" quat="1 0 0 0" mesh="mcp_joint" class="collision"/>
        <body name="pip_2" pos="-0.0122 0.0381 0.0145" quat="1 -1 -1 1">
          <inertial pos="0 0 0" quat="0.709913 0.704273 -0.000363156 0.00475427" mass="0.032"
            diaginertia="4.7981e-06 4.23406e-06 2.86184e-06"/>
          <joint name="mid_mcp_widen" range="-1.047 1.047" actuatorfrcrange="-5 5"/>
          <geom pos="0.00964336 0.0003 0.000784034" quat="1 -1 -1 -1" mesh="pip" class="obj_visual"/>
          <geom pos="0.00964336 0.0003 0.000784034" quat="1 -1 -1 -1" mesh="pip" class="collision"/>
          <body name="dip_2" pos="0.015 0.0143 -0.013" quat="1 1 -1 1">
            <inertial pos="0 0 0" quat="-0.252689 0.659216 0.238844 0.666735" mass="0.037"
              diaginertia="6.68256e-06 6.24841e-06 5.02002e-06"/>
            <joint name="mid_pip" range="-0.506 1.885" actuatorfrcrange="-5 5"/>
            <geom pos="0.0211334 -0.00843212 0.00978509" quat="0 -1 0 0" mesh="dip" class="obj_visual"/>
            <geom pos="0.0211334 -0.00843212 0.00978509" quat="0 -1 0 0" mesh="dip" class="collision"/>
            <body name="fingertip_2" pos="0 -0.0361 0.0002">
              <inertial pos="0 0 0" quat="0.706755 0.706755 0.0223155 0.0223155" mass="0.016"
                diaginertia="3.37527e-06 2.863e-06 1.54873e-06"/>
              <joint name="mid_dip" range="-0.366 2.042" actuatorfrcrange="-5 5"/>
              <geom pos="0.0132864 -0.00611424 0.0145" quat="0 1 0 0" mesh="fingertip" class="obj_visual"/>
              <geom pos="0.0132864 -0.00611424 0.0145" quat="0 1 0 0" mesh="fingertip" class="collision"/>
              <include file="mid_sensor_array.xml"/>  
            </body>
          </body>
        </body>
      </body>
      <body name="mcp_joint_3" pos="-0.00709525 -0.0678422 -0.0187224" quat="1 1 1 -1">
        <inertial pos="0 0 0" quat="0.388585 0.626468 -0.324549 0.592628" mass="0.044"
          diaginertia="1.47756e-05 1.31982e-05 6.0802e-06"/>
        <joint name="ring_mcp_bend" range="-0.314 2.23" actuatorfrcrange="-5 5"/>
        <geom pos="0.0084069 0.00776624 0.0146574" quat="1 0 0 0" mesh="mcp_joint" class="obj_visual"/>
        <geom pos="0.0084069 0.00776624 0.0146574" quat="1 0 0 0" mesh="mcp_joint" class="collision"/>
        <body name="pip_3" pos="-0.0122 0.0381 0.0145" quat="1 -1 -1 1">
          <inertial pos="0 0 0" quat="0.709913 0.704273 -0.000363156 0.00475427" mass="0.032"
            diaginertia="4.7981e-06 4.23406e-06 2.86184e-06"/>
          <joint name="ring_mcp_widen" range="-1.047 1.047" actuatorfrcrange="-5 5"/>
          <geom pos="0.00964336 0.0003 0.000784034" quat="1 -1 -1 -1" mesh="pip" class="obj_visual"/>
          <geom pos="0.00964336 0.0003 0.000784034" quat="1 -1 -1 -1" mesh="pip" class="collision"/>
          <body name="dip_3" pos="0.015 0.0143 -0.013" quat="1 1 -1 1">
            <inertial pos="0 0 0" quat="-0.252689 0.659216 0.238844 0.666735" mass="0.037"
              diaginertia="6.68256e-06 6.24841e-06 5.02002e-06"/>
            <joint name="ring_pip" range="-0.506 1.885" actuatorfrcrange="-5 5"/>
            <geom pos="0.0211334 -0.00843212 0.00978509" quat="0 -1 0 0" mesh="dip" class="obj_visual"/>
            <geom pos="0.0211334 -0.00843212 0.00978509" quat="0 -1 0 0" mesh="dip" class="collision"/>
            <body name="fingertip_3" pos="0 -0.0361 0.0002">
              <inertial pos="0 0 0" quat="0.706755 0.706755 0.0223155 0.0223155" mass="0.016"
                diaginertia="3.37527e-06 2.863e-06 1.54873e-06"/>
              <joint name="ring_dip" range="-0.366 2.042" actuatorfrcrange="-5 5"/>
              <geom pos="0.0132864 -0.00611424 0.0145" quat="0 1 0 0" mesh="fingertip" class="obj_visual"/>
              <geom pos="0.0132864 -0.00611424 0.0145" quat="0 1 0 0" mesh="fingertip" class="collision"/>
              <include file="ring_sensor_array.xml"/>  
            </body>
          </body>
        </body>
      </body>
      <body name="pip_4" pos="-0.0693952 -0.00124224 -0.0216224" quat="1 0 1 0">
        <inertial pos="0 0 0" quat="0.709913 0.704273 -0.000363156 0.00475427" mass="0.032"
          diaginertia="4.7981e-06 4.23406e-06 2.86184e-06"/>
        <joint name="thumb_mcp_range" range="-0.349 2.094" actuatorfrcrange="-5 5"/>
        <geom pos="-0.00535664 0.0003 0.000784034" quat="1 -1 -1 -1" mesh="pip" class="obj_visual"/>
        <geom pos="-0.00535664 0.0003 0.000784034" quat="1 -1 -1 -1" mesh="pip" class="collision"/>
        <body name="thumb_pip" pos="0 0.0143 -0.013" quat="1 1 -1 1">
          <inertial pos="0 0 0" mass="0.003" diaginertia="5.93e-07 5.49e-07 2.24e-07"/>
          <joint name="thumb_mcp_rotate" range="-0.47 2.443" actuatorfrcrange="-5 5"/>
          <geom pos="0.0119619 0 -0.0158526" quat="1 1 0 0" mesh="thumb_pip" class="obj_visual"/>
          <geom pos="0.0119619 0 -0.0158526" quat="1 1 0 0" mesh="thumb_pip" class="collision"/>
          <body name="thumb_dip" pos="0 0.0145 -0.017" quat="1 -1 0 0">
            <inertial pos="0 0 0" quat="0.708624 0.704906 0.00637342 0.0303153" mass="0.038"
              diaginertia="8.48742e-06 7.67823e-06 3.82835e-06"/>
            <joint name="thumb_pip" range="-1.2 1.9" actuatorfrcrange="-5 5"/>
            <geom pos="0.0439687 0.057953 -0.00862868" quat="1 0 0 0" mesh="thumb_dip" class="obj_visual"/>
            <geom pos="0.0439687 0.057953 -0.00862868" quat="1 0 0 0" mesh="thumb_dip" class="collision"/>
            <body name="thumb_fingertip" pos="0 0.0466 0.0002" quat="0 0 0 1">
              <inertial pos="0 0 0" quat="0.704307 0.709299 0.006848 -0.0282727" mass="0.049"
                diaginertia="2.03882e-05 1.98443e-05 4.32049e-06"/>
              <joint name="thumb_dip" range="-1.34 1.88" actuatorfrcrange="-5 5"/>
              <geom pos="0.0625595 0.0784597 0.0489929" quat="1 0 0 0" mesh="thumb_fingertip" class="obj_visual"/>
              <geom pos="0.0625595 0.0784597 0.0489929" quat="1 0 0 0" mesh="thumb_fingertip" class="collision"/>
              <include file="thumb_sensor_array.xml"/>  
            </body>
          </body>
        </body>
      </body>
    </body>
  </worldbody>

  <contact>
    <exclude body1="palm_lower" body2="mcp_joint"/>
    <exclude body1="palm_lower" body2="mcp_joint_2"/>
    <exclude body1="palm_lower" body2="mcp_joint_3"/>
    <exclude body1="palm_lower" body2="thumb_dip"/>
    <exclude body1="palm_lower" body2="thumb_pip"/>
    <exclude body1="palm_lower" body2="pip_4"/>
    <exclude body1="mcp_joint" body2="dip"/>
    <exclude body1="mcp_joint_3" body2="dip_3"/>
    <exclude body1="mcp_joint_2" body2="dip_2"/>
  </contact>

  <actuator>
    <position class="right_leap" name="index_mcp_bend" joint="index_mcp_bend" />
    <position class="right_leap" name="index_mcp_widen" joint="index_mcp_widen" />
    <position class="right_leap" name="index_pip" joint="index_pip" />
    <position class="right_leap" name="index_dip" joint="index_dip" />
    <position class="right_leap" name="mid_mcp_bend" joint="mid_mcp_bend" />
    <position class="right_leap" name="mid_mcp_widen" joint="mid_mcp_widen" />
    <position class="right_leap" name="mid_pip" joint="mid_pip" />
    <position class="right_leap" name="mid_dip" joint="mid_dip" />
    <position class="right_leap" name="ring_mcp_bend" joint="ring_mcp_bend" />
    <position class="right_leap" name="ring_mcp_widen" joint="ring_mcp_widen" />
    <position class="right_leap" name="ring_pip" joint="ring_pip" />
    <position class="right_leap" name="ring_dip" joint="ring_dip" />
    <position class="right_leap" name="thumb_mcp_range" joint="thumb_mcp_range" />
    <position class="right_leap" name="thumb_mcp_rotate" joint="thumb_mcp_rotate" />
    <position class="right_leap" name="thumb_pip" joint="thumb_pip" />
    <position class="right_leap" name="thumb_dip" joint="thumb_dip" />
  </actuator>

  <sensor>
    <include file="sensor_include.xml"/>  
  </sensor>
</mujoco>
