<mujoco model="air_arm">

  <include file="../../scene.xml"/>
  <include file="../../airbot_play/airbot_play_dependencies.xml"/>

  <option integrator="RK4" solver="Newton" />
  <compiler angle="radian" inertiafromgeom="auto" inertiagrouprange="4 5" meshdir="../../../meshes/" texturedir="../../../textures/"/>
  <size njmax="10000" nconmax="10000"/>

  <contact>
    <exclude body1='arm_base' body2='link2'/>
  </contact>

  <worldbody>
    <!-- ======= AITBOT PLAY ======= -->
    <body name="arm_base" pos="0 0 0.78" euler="0 0 0">
      <geom type="box" pos="-0.02 0 0.005" size="0.0806 0.1375 0.0025" rgba="0.2 0.2 0.2 1"/>
      <geom mesh="arm_base_0" pos="0 0 -0.0015" material="Gree_Light_Base" class="obj_visual"/>
      <geom mesh="arm_base_1" material="Paint_Matte_Black" class="obj_visual"/>
      <body name="link1" pos="0 0 0.1172">
        <inertial pos="7.9126e-05 -0.002527 -0.0041359" quat="0.696716 0.716558 0.0238919 -0.0236876" mass="0.54639" diaginertia="0.000346294 0.000325437 0.000286269"/>
        <joint name="joint1" class="joint1"/>
        <geom type="mesh" contype="0" conaffinity="0" density="0" rgba="0.1 0.1 0.1 1" mesh="link1"/>
        <body name="link2" quat="0.135866 0.135867 -0.69393 0.693932">
          <inertial pos="0.22493 0.0047721 0.008023" quat="-0.210875 0.632473 -0.273056 0.693506" mass="0.64621" diaginertia="0.00516535 0.00505042 0.000418626"/>
          <joint name="joint2" class="joint2"/>
          <geom type="box" pos="0.08 0.015 0" euler="0 0 0.15" size="0.11 0.03 0.04" rgba="1 0 0 0"/>
          <geom type="box" pos="0.235 0.015 0" euler="0 0 -0.3" size="0.065 0.025 0.045" rgba="1 0 0 0"/>
          <geom mesh="link2_0" material="Paint_Matte_Black" class="obj_visual"/>
          <geom mesh="link2_1" material="Paint_Metallic_Cool_Grey" class="obj_visual"/>
          <body name="link3" pos="0.27009 0 0" quat="0.192144 0 0 -0.981367">
            <inertial pos="0.16813 -5.5576e-05 0.0031184" quat="0.511278 0.488423 0.489191 0.510617" mass="0.26829" diaginertia="0.0031527 0.0030951 0.000239403"/>
            <joint name="joint3" class="joint3"/>
            <geom type="box" pos="0.13 0 0" size="0.13 0.025 0.025" rgba="1 0 0 0"/>
            <geom mesh="link3_0" material="Paint_Matte_Black" class="obj_visual"/>
            <geom mesh="link3_1" material="Paint_Metallic_Cool_Grey" class="obj_visual"/>
            <body name="link4" pos="0.29015 0 0" quat="-2.59734e-06 0.707105 2.59735e-06 0.707108">
              <inertial pos="5.2436e-06 0.00040412 -0.03228" quat="0.999969 -0.000174762 -0.00792041 -6.98144e-05" mass="0.34876" diaginertia="0.000423574 0.000412 0.000126826"/>
              <joint name="joint4" class="joint4"/>
              <geom type="mesh" rgba="0.1 0.1 0.1 1" mesh="link4"/>
              <body name="link5" quat="0.707105 0.707108 0 0">
                <inertial pos="8.3328e-06 0.026148 0.002525" quat="0.531568 0.4663 0.4663 0.531568" mass="0.36132" diaginertia="0.0004677 0.000432922 0.000178178"/>
                <joint name="joint5" class="joint5"/>
                <geom mesh="link5_0" material="Paint_Matte_Black" class="obj_visual"/>
                <geom mesh="link5_1" material="Paint_Metallic_Cool_Grey" class="obj_visual"/>
                <body name="link6" pos="0 0.23645 0" quat="0.499998 -0.5 0.5 0.500002">
                  <inertial pos="-0.0047053 7.3857e-05 -0.12293" mass="0.53855" diaginertia="5e-05 5e-05 3.85e-05"/>
                  <joint name="joint6" class="joint6"/>
                  <site name="endpoint" pos='0 0 0' euler="0 -1.5708 0" size='0.001' type='sphere'/>
                </body>
              </body>
            </body>
          </body>
        </body>
      </body>
    </body>

    <!-- ======= TABLE write ======= -->
    <body name="table-a" pos="0 0 0">
      <geom size="0.3 0.6 0.01" pos="0 0 0.77" type="box" rgba="0.8 0.8 0.8 1" condim="4" solimp="2 1 0.01" solref="0.01 1" friction="1 0.005 0.0001"/>
      <geom size="0.02 0.02 0.385" pos=" 0.28  0.56 0.385" type="box" contype="0" conaffinity="0" rgba="0.8 0.8 0.8 1" />
      <geom size="0.02 0.02 0.385" pos="-0.28  0.56 0.385" type="box" contype="0" conaffinity="0" rgba="0.8 0.8 0.8 1" />
      <geom size="0.02 0.02 0.385" pos=" 0.28 -0.56 0.385" type="box" contype="0" conaffinity="0" rgba="0.8 0.8 0.8 1" />
      <geom size="0.02 0.02 0.385" pos="-0.28 -0.56 0.385" type="box" contype="0" conaffinity="0" rgba="0.8 0.8 0.8 1" />
    </body>
  </worldbody>

  <actuator>
    <position name="joint1" ctrllimited="true" ctrlrange="-3.14 2.09"  joint="joint1" kp="1000" user="1" forcelimited="true" forcerange="-300 300"/>
    <position name="joint2" ctrllimited="true" ctrlrange="-2.96 0.17"  joint="joint2" kp="1000" user="1" forcelimited="true" forcerange="-300 300"/>
    <position name="joint3" ctrllimited="true" ctrlrange="-0.087 3.14" joint="joint3" kp="1000" user="1" forcelimited="true" forcerange="-300 300"/>
    <position name="joint4" ctrllimited="true" ctrlrange="-2.96 2.96"  joint="joint4" kp="350" user="1" forcelimited="true" forcerange="-300 300"/>
    <position name="joint5" ctrllimited="true" ctrlrange="-1.74 1.74"  joint="joint5" kp="350" user="1" forcelimited="true" forcerange="-300 300"/>
    <position name="joint6" ctrllimited="true" ctrlrange="-3.14 3.14"  joint="joint6" kp="100" user="1" forcelimited="true" forcerange="-300 300"/>
  </actuator>

  <sensor>
    <jointpos name="joint1_pos" joint="joint1" />
    <jointpos name="joint2_pos" joint="joint2" />
    <jointpos name="joint3_pos" joint="joint3" />
    <jointpos name="joint4_pos" joint="joint4" />
    <jointpos name="joint5_pos" joint="joint5" />
    <jointpos name="joint6_pos" joint="joint6" />

    <jointvel name="joint1_vel" joint="joint1" />
    <jointvel name="joint2_vel" joint="joint2" />
    <jointvel name="joint3_vel" joint="joint3" />
    <jointvel name="joint4_vel" joint="joint4" />
    <jointvel name="joint5_vel" joint="joint5" />
    <jointvel name="joint6_vel" joint="joint6" />

    <jointactuatorfrc name="joint1_torque" joint="joint1" />
    <jointactuatorfrc name="joint2_torque" joint="joint2" />
    <jointactuatorfrc name="joint3_torque" joint="joint3" />
    <jointactuatorfrc name="joint4_torque" joint="joint4" />
    <jointactuatorfrc name="joint5_torque" joint="joint5" />
    <jointactuatorfrc name="joint6_torque" joint="joint6" />

    <framepos name="endpoint_pos" objtype="site" objname="endpoint" reftype="body" refname="arm_base"/>
    <framequat name="endpoint_quat" objtype="site" objname="endpoint" reftype="body" refname="arm_base"/>
    <framelinvel name="endpoint_vel" objtype="site" objname="endpoint" reftype="body" refname="arm_base"/>
    <gyro name="endpoint_gyro" site="endpoint"/>
    <accelerometer name="endpoint_acc" site="endpoint" />
  </sensor>

  <keyframe>
    <key qpos='0 0 0 0 0 0'/>
  </keyframe>

</mujoco>
