<mujoco model="free_camera">
  <option integrator="RK4" solver="Newton" gravity="0 0 0"/>
  <compiler angle="radian" meshdir="../meshes" texturedir="../textures/"/>

  <visual>
    <global offwidth="1920" offheight="1080"/>
    <quality shadowsize="4096" offsamples="4"/>
    <headlight diffuse='0.6 0.6 0.6' ambient='.3 .3 .3' specular='0 0 0'/>
    <scale com="0.05" camera="0.06" framelength="0.5" framewidth="0.02" forcewidth="0.1" contactwidth="0.01" contactheight="0.05"/>
  </visual>

  <asset>
    <texture type='2d' name='groundplane' builtin='checker' mark='edge' rgb1='0.2 0.3 0.4' rgb2='0.1 0.2 0.3' markrgb='0.8 0.8 0.8' width='300' height='300'/>
    <material name='groundplane' texture='groundplane' texuniform='true' texrepeat='5 5' reflectance='0.2'/>
  </asset>

  <worldbody>
    <light castshadow="false" directional='true' diffuse='.3 .3 .3' specular='0.3 0.3 0.3' pos='-1 -1 1' dir='1 1 -1'/>
    <light directional='true' diffuse='.3 .3 .3' specular='0.3 0.3 0.3' pos='0 0 1' dir='-1 1 -1'/>
    <light castshadow="false" directional='true' diffuse='.3 .3 .3' specular='0.3 0.3 0.3' pos='0 1 1' dir='0 -1 -1'/>
    <geom name='floor' type='plane' size='0 0 0.01' material='groundplane' pos='0 0 0'/>

    <body name="dummy_robot" pos="0 0 1">
      <body euler="0 -1.5708 -1.5708">
        <joint axis='-1 0 0' range="-1.5708 1.5708"/>
        <inertial pos="0 0 0" mass="0.001" diaginertia="1e-5 1e-5 1e-5"/>
        <camera name='_dummy_robot'/>
        <site name="dummy_robot" euler="3.1416 0 0" size='0.001' type='sphere'/>
      </body>
      <geom type="box" size="0.1 0.1 0.1" rgba="1 1 1 0.1"/>
    </body>

    <geom type="box" pos="0.5 0 1" size="0.01 0.03 0.1" rgba="1 0 0 1"/>


  </worldbody>

</mujoco>
