<mujocoinclude>

  <geom size="0.195 0.555 0.019" pos="0 0 0.019" type="box" rgba="1 1 1 1"/>
  <geom size="0.195 0.555 0.0075" pos="0 0 0.38" type="box" rgba="1 1 1 1"/>
  <geom size="0.195 0.555 0.0075" pos="0 0 0.38" type="box" rgba="1 1 1 1"/>
  <geom size="0.195 0.555 0.0075" pos="0 0 0.73" type="box" rgba="1 1 1 1"/>
  <geom size="0.195 0.555 0.0075" pos="0 0 1.08" type="box" rgba="1 1 1 1"/>
  <geom size="0.195 0.555 0.019" pos="0 0 1.451" type="box" rgba="1 1 1 1"/>

  <geom size="0.195 0.019 0.735" pos="0 0.55 0.735" type="box" rgba="1 1 1 1"/>
  <geom size="0.195 0.0075 0.735" pos="0 0.169 0.735" type="box" rgba="1 1 1 1"/>
  <geom size="0.195 0.0075 0.735" pos="0 -0.169 0.735" type="box" rgba="1 1 1 1"/>
  <geom size="0.195 0.019 0.735" pos="0 -0.55 0.735" type="box" rgba="1 1 1 1"/>

  <body pos="-0.2 0 0.9875">
    <body name="drawer_1" pos="-0.0075 0.003 0.005">
      <joint range='0 0.3' type='slide' axis='-1 0 0' frictionloss="0.05"/>
      <inertial pos="0.1 0 0" quat="1 0 0 0" mass="0.011566" diaginertia="0.000035528 0.000021045 0.000021045"/>

      <geom size="0.005 0.007" pos="-0.002 0 0" euler="0 1.5708 0" type="cylinder" condim="4" solimp="2 1 0.01" solref="0.01 1" friction="1 0.005 0.0001" rgba=".1 .1 .1 1"/>
      <geom size="0.010 0.002" pos="-0.012 0 0" euler="0 1.5708 0" type="cylinder" condim="4" solimp="2 1 0.01" solref="0.01 1" friction="1 0.005 0.0001" rgba=".1 .1 .1 1"/>

      <geom size="0.0075 0.158 0.081" pos="0.015 -0.003 -0.005" type="box" rgba=".9 .9 .8 1"/>
      <geom size="0.165 0.006 0.035" pos="0.181 0.144 -0.026" type="box" rgba=".9 .9 .8 1"/>
      <geom size="0.165 0.006 0.035" pos="0.181 -0.144 -0.026" type="box" rgba=".9 .9 .8 1"/>
      <geom size="0.006 0.14 0.035" pos="0.33 0 -0.026" type="box" rgba=".9 .9 .8 1"/>
      <geom size="0.16 0.14 0.006" pos="0.175 0 -0.061" type="box" rgba=".9 .9 .8 1"/>

      <site name="drawer_1_handle" pos='-0.01 0 0' euler="0 0 3.1416" size='0.001' type='sphere'/>
    </body>
  </body>

  <body name="drawer_2" pos="-0.2 0 0.8225">
    <joint range='0 0.9' type='slide' axis='-1 0 0' frictionloss="0.05"/>
    <inertial pos="0.1 0 0" quat="1 0 0 0" mass="0.011566" diaginertia="0.000035528 0.000021045 0.000021045"/>

    <geom size="0.005 0.015" pos="-0.015 0.065 0" euler="0 1.5708 0" type="cylinder" condim="4" solimp="2 1 0.01" solref="0.001 1" friction="1 0.005 0.0001" rgba=".1 .1 .1 1"/>
    <geom size="0.005 0.015" pos="-0.015 -0.065 0" euler="0 1.5708 0" type="cylinder" condim="4" solimp="2 1 0.01" solref="0.001 1" friction="1 0.005 0.0001" rgba=".1 .1 .1 1"/>
    <geom size="0.005 0.065" pos="-0.03 0 0" euler="1.5708 0 0" type="cylinder" condim="4" solimp="2 1 0.01" solref="0.001 1" friction="10 10 10" rgba=".1 .1 .1 1"/>

    <geom size="0.0075 0.158 0.081" pos="0.0075 0 0" type="box" rgba=".9 .9 .8 1"/>
    <geom size="0.165 0.006 0.035" pos="0.181 0.144 -0.026" type="box" rgba=".9 .9 .8 1"/>
    <geom size="0.165 0.006 0.035" pos="0.181 -0.144 -0.026" type="box" rgba=".9 .9 .8 1"/>
    <geom size="0.006 0.14 0.035" pos="0.33 0 -0.026" type="box" rgba=".9 .9 .8 1"/>
    <geom size="0.16 0.14 0.006" pos="0.165 0 -0.061" type="box" rgba=".9 .9 .8 1"/>

    <site name="drawer_2_handle" pos='-0.03 0 0' euler="0 0 3.1416" size='0.001' type='sphere'/>

  </body>

</mujocoinclude>
