<mujocoinclude>

  <body name='agv_link' pos='0.02371 0 0'>

    <site name="base_link" pos='-0.02371 0 0' size='0.001' type='sphere'/>

    <site name="laser" pos='0.09 0 0.215' size='0.001' type='sphere'/>

    <geom mesh="mmk2_agv_0" material="Paint_Matte_Black__1" class="obj_visual"/>
    <geom mesh="mmk2_agv_1" material="Copper_Textured__1_1" class="obj_visual"/>
    <geom mesh="mmk2_agv_2" material="Paint_Metallic_Cool_Grey__1" class="obj_visual"/>
    <geom mesh="mmk2_agv_3" material="Paint_Matte_Black__1" class="obj_visual"/>
    <geom mesh="mmk2_agv_4" rgba="0.592 0.9 0.9 1" class="obj_visual"/>

    <geom euler="0 0 0" type="box" rgba="1 0 0 1" group="4" size="0.21 0.2 0.005" pos="-0.015 0 0.235" density="725.0"/>
    <geom euler="0 0 0" type="box" rgba="1 0 0 1" group="4" size="0.21 0.2 0.08" pos="-0.015 0 0.11" density="725.0"/>
    <geom type="box" rgba="1 0 0 1" group="4" size="0.125 0.15 0.675" pos="-0.08 0 0.915" density="200.0"/>

    <geom name='rgt_front_wheel'  pos=" 0.13045 -0.089989 0.0585" mass='1.1566' type="sphere" size='0.06' rgba="1 0 0 1" group="4" condim='1' priority='1'/>
    <geom name='lft_front_wheel'  pos=" 0.13045  0.090011 0.0585" mass='1.1566' type="sphere" size='0.06' rgba="1 0 0 1" group="4" condim='1' priority='1'/>
    <geom name='rgt_behind_wheel' pos="-0.15755 -0.099989 0.0585" mass='1.1566' type="sphere" size='0.06' rgba="1 0 0 1" group="4" condim='1' priority='1'/>
    <geom name='lft_behind_wheel' pos="-0.15755  0.10001  0.0585" mass='1.1566' type="sphere" size='0.06' rgba="1 0 0 1" group="4" condim='1' priority='1'/>

    <geom mesh='rgt_front_wheel_link'  euler="0 0 1.5708" pos=" 0.13045 -0.089989 0.085" rgba="0.2 0.2 0.2 1" class="obj_visual"/>
    <geom mesh='lft_front_wheel_link'  euler="0 0 1.5708" pos=" 0.13045  0.090011 0.085" rgba="0.2 0.2 0.2 1" class="obj_visual"/>
    <geom mesh='rgt_behind_wheel_link' euler="0 0 1.5708" pos="-0.15755 -0.099989 0.085" rgba="0.2 0.2 0.2 1" class="obj_visual"/>
    <geom mesh='lft_behind_wheel_link' euler="0 0 1.5708" pos="-0.15755  0.10001  0.085" rgba="0.2 0.2 0.2 1" class="obj_visual"/>

    <geom pos="-0.006 0 0.244" euler="0 0 1.5708" mesh="mmk2_lift_link_0" rgba="0.57 0.95 0.95 1" class="obj_visual"/>
    <geom pos="-0.0062 0 0.24" euler="0 0 1.5708" mesh="mmk2_lift_link_1" material="Paint_Metallic_Cool_Grey__1" class="obj_visual"/>
    <geom pos="0.002 0 0.264" euler="0 0 1.5708" mesh="mmk2_lift_link_2" material="Paint_Matte_Black__1" class="obj_visual"/>

    <body name="lft_wheel_link" pos="-0.02371 0.16325 0.082" euler="1.5707963267948966 0 0">
      <inertial pos="2.9309e-07 5.2077e-06 -0.029871" quat="0.28052 0.649078 -0.280681 0.649018" mass="1.1566" diaginertia="0.0035528 0.0021045 0.0021045"/>
      <joint name="lft_wheel_joint" class='wheel'/>
      <geom name='lft_wheel' type="mesh" rgba="0.2 0.2 0.2 1" mesh="lft_wheel_link" class="obj_visual"/>
      <geom pos="0 0 0" type="cylinder" size='0.0838 0.005' rgba="0 1 0 1" group="4" friction="0.95"/>
    </body>

    <body name="rgt_wheel_link" pos="-0.02371 -0.16325 0.082" euler="1.5707963267948966 0 0">
      <inertial pos="2.9312e-07 5.2196e-06 0.029871" quat="0.620108 0.339813 -0.620017 0.339959" mass="1.1566" diaginertia="0.0035528 0.0021045 0.0021045"/>
      <joint name="rgt_wheel_joint" class='wheel'/>
      <geom name='rgt_wheel' type="mesh" rgba="0.2 0.2 0.2 1" mesh="rgt_wheel_link" class="obj_visual"/>
      <geom pos="0 0 0" type="cylinder" size='0.0838 0.005' rgba="0 1 0 1" group="4" friction="0.95"/>
    </body>

    <body name="slide_link" pos="0 0 1.311">
      <joint name="slide_joint" class='slide_joint'/>
      <geom mesh="slide_link_black" material="Clear_Shiny_Plastic_Black__1" class="obj_visual"/>
      <geom mesh="slide_link_white" material="Paint_Metallic_Cool_Grey__1" class="obj_visual"/>
      <geom euler="0 0 0.7854" type="box" rgba="1 0 0 1" group="4" size="0.15 0.15 0.1" pos="0.035 0 0" density="80.0"/>
      <include file="head.xml"/>

      <body name="lft_arm_base" pos="0.034 0.1015 0" quat="0.65328 -0.65328 0.2706 -0.2706">
        <geom mesh="arm_base_1" material="Paint_Matte_Black" class="obj_visual"/>
        <include file="arm_left.xml"/>
      </body>

      <body name="rgt_arm_base" pos="0.034 -0.1015 0" quat="0.65328 0.65328 0.2706 0.2706">
        <geom mesh="arm_base_1" material="Paint_Matte_Black" class="obj_visual"/>
        <include file="arm_right.xml"/>
      </body>
    </body>

  </body>

</mujocoinclude>
